Workbook

Sheet Input survey A
A1: Input survey A
A2: Dati survey selezionati e mantenuti separati dal calcolo della matrice.
A3: File origine | B3: chat_Galactica_Prova_calcolo score.xlsx
A4: Foglio origine | B4: Sheet0
A5: Riga origine selezionata | B5: 3
A6: Ragione sociale | B6: GM Spa
A7: Tipo impresa | B7: PMI
A8: Peso usato nella simulazione | B8: Peso PMI
A11: Codice domanda | B11: Testo domanda | C11: Risposta survey | D11: Presente in mappatura 2.0 | E11: Nota
A12: CQ1 | B12: Le persone sono e si sentono libere di esprimere il proprio punto di vista e il proprio disaccordo? ⓘ | C12: 3 | D12: Sì
A13: CQ2 | B13: Esistono spazi e strumenti strutturati in cui le persone possano proporre miglioramenti? ⓘ | C13: 1 | D13: Sì
A14: CQ3 | B14: Il linguaggio interno tiene in considerazione le diverse identità quali ad esempio il genere, i background culturali, il livello di istruzione? ⓘ | C14: 3 | D14: Sì
A15: CQ4 | B15: Esistono procedure e policy formalizzate per prevenire, contrastare e segnalare episodi di discriminazione, pregiudizio o microaggressioni? ⓘ | C15: 2 | D15: Sì
A16: CQ5 | B16: L’organizzazione prende in considerazione il tema della sicurezza psicologica? ⓘ | C16: 4 | D16: Sì
A17: PQ1 | B17: La comunicazione interna è accessibile? ⓘ | C17: 2 | D17: Sì
A18: PQ2 | B18: È presente un programma di inserimento (onboarding) per persone neo-assunte che promuove il valore dell'inclusione? ⓘ | C18: 2 | D18: Sì
A19: PQ3 | B19: Sono presenti misure di flessibilità e conciliazione vita-lavoro per supportare tutte le persone? ⓘ | C19: 3 | D19: Sì
A20: PQ4 | B20: L'organizzazione monitora l’accesso e l’utilizzo dei congedi parentali e familiari? ⓘ | C20: 1 | D20: Sì
A21: PQ5 | B21: L’organizzazione riflette e agisce sul rapporto tra longevità lavorativa, avanzamenti di carriera, sostenibilità dei ruoli e benessere delle persone nelle diverse fasi della vita professionale? ⓘ | C21: 2 | D21: Sì
A22: PQ6 | B22: I processi HR considerano le specificità delle diverse identità, garantendo opportunità eque? ⓘ | C22: 2 | D22: Sì
A23: PQ7 | B23: L'organizzazione prevede formazione per promuovere opportunità eque di carriera e lo sviluppo continuo delle competenze professionali? ⓘ | C23: 1 | D23: Sì
... A60: MQ17 | B60: La politica di qualifica, selezione, rinnovo e audit dei fornitori prevede il rispetto dei criteri DEIA e li monitora nel tempo? ⓘ | C60: 2 | D60: Sì
A61: MQ18 | B61: L’organizzazione coinvolge fornitori e altri partner esterni in iniziative o attività relative alla DEIA? ⓘ | C61: 2 | D61: No | E61: Presente nella survey ma assente nella mappatura 2.0
A62: SQ7 | B62: L’organizzazione conduce analisi periodiche dei bisogni legati alla DEIA? ⓘ | C62: 3 | D62: Sì
A63: SQ8 | B63: Sono presenti KPI per misurare e monitorare in modo strutturato le iniziative e le politiche DEIA? ⓘ | C63: 3 | D63: Sì
A64: SQ9 | B64: La DEIA è inclusa nei valori dell'organizzazione? ⓘ | C64: 2 | D64: Sì
A65: SQ10 | B65: La DEIA è integrata in modo strutturale nella visione strategica dell'organizzazione? ⓘ | C65: 2 | D65: Sì
A66: SQ11 | B66: L'organizzazione ha un piano strategico DEIA pluriennale con obiettivi chiari e misurabili? ⓘ | C66: 3 | D66: Sì
A67: SQ12 | B67: In che misura l'organizzazione assume decisioni finanziarie (es. budget, investimenti, incentivi) che tengono esplicitamente conto di obiettivi di diversità, equità, inclusione e accessibilità? ⓘ | C67: 1 | D67: Sì
A71: Score A originali presenti nel file survey (non usati direttamente nella matrice C)
A72: Voce score originale | B72: Valore
A73: PROCESSI score | B73: 2.0488
A74: CULTURA score | B74: 2.4
A75: STRATEGIA score | B75: 1.98
A76: MERCATO score | B76: 2.1828
A77: CULTURA | CULTURA E COMPORTAMENTI score | B77: 2.1429
A78: CULTURA | BENESSERE E SICUREZZA PSICOLOGICA score | B78: 3.4286
A79: PROCESSI | PROCESSI OPERATIVI E ACCESSIBILITÀ score | B79: 1.625
A80: PROCESSI | PERSONE E PROCESSI score | B80: 2.1522
A81: CULTURA | FORMAZIONE E CONSAPEVOLEZZA score | B81: 2
...

Sheet Input esterno GIorgia-per axY 
A1: Input reporting B
A2: Dati di content analysis; valori tema per tema mantenuti come interi 1-4.
A3: File origine | B3: Dataset reporting-0107.xlsx
A4: Foglio origine | B4: Dataset_reporting
A5: Caso reporting selezionato per matrice | B5: 4BILD S.p.A.
A6: Nota simulazione | B6: Il caso reporting selezionato è usato come proxy di prova perché non esiste GM Spa nel dataset reporting.
A8: Azienda | B8: Dimensione | C8: Tema reporting | D8: Score reporting | E8: Usato matrice | F8: Chiave lookup | G8: Riga fonte dataset | H8: Nota
A9: 4BILD S.p.A. | B9: PMI | C9: Foundation | D9: 4 | E9: Sì | F9: 4BILD S.p.A.|Foundation | G9: 2
A10: 4BILD S.p.A. | B10: PMI | C10: HR | D10: 3 | E10: Sì | F10: 4BILD S.p.A.|HR | G10: 2
A11: 4BILD S.p.A. | B11: PMI | C11: Employment | D11: 3 | E11: Sì | F11: 4BILD S.p.A.|Employment | G11: 2
A12: 4BILD S.p.A. | B12: PMI | C12: Employees Engagement | D12: 3 | E12: Sì | F12: 4BILD S.p.A.|Employees Engagement | G12: 2
A13: 4BILD S.p.A. | B13: PMI | C13: Education & Training | D13: 3 | E13: Sì | F13: 4BILD S.p.A.|Education & Training | G13: 2
A14: 4BILD S.p.A. | B14: PMI | C14: Non-discrimination | D14: 4 | E14: Sì | F14: 4BILD S.p.A.|Non-discrimination | G14: 2
A15: 4BILD S.p.A. | B15: PMI | C15: Monitoring | D15: 3 | E15: Sì | F15: 4BILD S.p.A.|Monitoring | G15: 2
A16: 4BILD S.p.A. | B16: PMI | C16: Supply Chain Diversity | D16: 3 | E16: Sì | F16: 4BILD S.p.A.|Supply Chain Diversity | G16: 2 | H16: Usata la prima colonna Supply Chain; la colonna duplicata Supply chain è mantenuta nel raw data.
A17: 4BILD S.p.A. | B17: PMI | C17: Communities | D17: 3 | E17: Sì | F17: 4BILD S.p.A.|Communities | G17: 2
A18: 4BILD S.p.A. | B18: PMI | C18: End-users | D18: 2 | E18: Sì | F18: 4BILD S.p.A.|End-users | G18: 2
A19: Fater S.p.A. | B19: Grande impresa | C19: Foundation | D19: 3 | E19: No | F19: Fater S.p.A.|Foundation | G19: 3
A20: Fater S.p.A. | B20: Grande impresa | C20: HR | D20: 3 | E20: No | F20: Fater S.p.A.|HR | G20: 3
A21: Fater S.p.A. | B21: Grande impresa | C21: Employment | D21: 4 | E21: No | F21: Fater S.p.A.|Employment | G21: 3
A22: Fater S.p.A. | B22: Grande impresa | C22: Employees Engagement | D22: 4 | E22: No | F22: Fater S.p.A.|Employees Engagement | G22: 3
A23: Fater S.p.A. | B23: Grande impresa | C23: Education & Training | D23: 1 | E23: No | F23: Fater S.p.A.|Education & Training | G23: 3
A24: Fater S.p.A. | B24: Grande impresa | C24: Non-discrimination | D24: 3 | E24: No | F24: Fater S.p.A.|Non-discrimination | G24: 3
A25: Fater S.p.A. | B25: Grande impresa | C25: Monitoring | D25: 4 | E25: No | F25: Fater S.p.A.|Monitoring | G25: 3
A26: Fater S.p.A. | B26: Grande impresa | C26: Supply Chain Diversity | D26: 3 | E26: No | F26: Fater S.p.A.|Supply Chain Diversity | G26: 3 | H26: Usata la prima colonna Supply Chain; la colonna duplicata Supply chain è mantenuta nel raw data.
A27: Fater S.p.A. | B27: Grande impresa | C27: Communities | D27: 4 | E27: No | F27: Fater S.p.A.|Communities | G27: 3
A28: Fater S.p.A. | B28: Grande impresa | C28: End-users | D28: 2 | E28: No | F28: Fater S.p.A.|End-users | G28: 3
A29: Iveco Group N.V. | B29: Grande impresa | C29: Foundation | D29: 4 | E29: No | F29: Iveco Group N.V.|Foundation | G29: 4
A30: Iveco Group N.V. | B30: Grande impresa | C30: HR | D30: 4 | E30: No | F30: Iveco Group N.V.|HR | G30: 4
A31: Iveco Group N.V. | B31: Grande impresa | C31: Employment | D31: 4 | E31: No | F31: Iveco Group N.V.|Employment | G31: 4
A32: Iveco Group N.V. | B32: Grande impresa | C32: Employees Engagement | D32: 4 | E32: No | F32: Iveco Group N.V.|Employees Engagement | G32: 4
A33: Iveco Group N.V. | B33: Grande impresa | C33: Education & Training | D33: 4 | E33: No | F33: Iveco Group N.V.|Education & Training | G33: 4
A34: Iveco Group N.V. | B34: Grande impresa | C34: Non-discrimination | D34: 4 | E34: No | F34: Iveco Group N.V.|Non-discrimination | G34: 4
A35: Iveco Group N.V. | B35: Grande impresa | C35: Monitoring | D35: 4 | E35: No | F35: Iveco Group N.V.|Monitoring | G35: 4
A36: Iveco Group N.V. | B36: Grande impresa | C36: Supply Chain Diversity | D36: 4 | E36: No | F36: Iveco Group N.V.|Supply Chain Diversity | G36: 4 | H36: Usata la prima colonna Supply Chain; la colonna duplicata Supply chain è mantenuta nel raw data.
A37: Iveco Group N.V. | B37: Grande impresa | C37: Communities | D37: 4 | E37: No | F37: Iveco Group N.V.|Communities | G37: 4
A38: Iveco Group N.V. | B38: Grande impresa | C38: End-users | D38: 3 | E38: No | F38: Iveco Group N.V.|End-users | G38: 4
A42: Dati originali wide dal foglio Dataset_reporting
A43: Nome azienda | B43: P.IVA | C43: Dimensione | D43: Settore | E43: Tipologia Report | F43: Standards / Guidelines | G43: Tipologia analisi materialità | H43: Sezione specifica DEIA reporting | I43: DEIA website (Link) | J43: Foundation | K43: HR | L43: Employment | M43: Employees Engagement | N43: Education & Training | O43: Non-discrimination | P43: Monitoring | Q43: Supply Chain | R43: Communities | S43: End-users | T43: Supply chain | U43: Score | V43: Religione e credo | W43: Disabilità | X43: Generazioni ed età | Y43: Etnia | Z43: Genere | AA43: LGBTQIA+ | AB43: Status socio-economico | AC43: Aspetto Fisico | AD43: Score | AE43: Note
A44: 4BILD S.p.A. | B44: 07501260967 | C44: PMI | D44: Distribuzione materiali edili | E44: Bilancio di sostenibilità 2024 | F44: GRI Standards; SDGs/Agenda 2030; analisi di doppia materialità | G44: Doppia materialità con stakeholder engagement e questionario ESG | H44: Sì - capitolo Persone, sezione 5.3 Benessere personale e principi D&I | I44: https://www.4bild.it/4bild-di-e-parita-di-genere/ | J44: 4 | K44: 3 | L44: 3 | M44: 3 | N44: 3 | O44: 4 | P44: 3 | Q44: 3 | R44: 3 | S44: 2 | T44: 2 | U44: 3 | V44: 1 | W44: 1 | X44: 3 | Y44: 1 | Z44: 4 | AA44: 1 | AB44: 2 | AC44: 1 | AD44: 1.75 | AE44: Evidenze: primo bilancio di sostenibilità; valori e sfide includono D&I/parità di genere e diversità come valore (pp. 8, 16-17, 22-23); D&I e non discriminazione sono tema materiale GRI 405/406 (pp. 30-33). Policy D&I e parità di genere approvata 23/10/2024, UNI/PdR 125:2022, zero tolerance su discriminazioni/molestie, pari opportunità formative/crescita/retribuzione, empowerment femminile, feedback e monitoraggio annuale (pp. 54-57, 64-65). KPI occupazione/turnover per genere/età e 4BILD Accademia (pp. 58-63). Comunità: WECARE, Perù/Rwanda e sponsorizzazioni (pp. 66-67). Criticità: supplier diversity, religione, disabilità, etnia, LGBTQIA+, aspetto fisico e accessibilità end-user poco o non rendicontati.
...

Sheet Mappatura A-B-C
A1: Mappatura A-B-C
A2: Mappatura operativa tra domande survey e temi reporting con pesi, quote 70/30 e contributi al calcolo.
A4: Riga fonte | B4: N. | C4: Cod. domanda | D4: Framework diversity | E4: Sottogruppo | F4: Cod. standard | G4: Cod. 1 | H4: Cod. 2 | I4: Tema 1 | J4: % alloc. 1 | K4: Tema 2 | L4: % alloc. 2 | M4: Peso PMI | N4: Peso GRANDI | O4: Risposta survey | P4: Risposta finale | Q4: Inclusa matrice | R4: Motivo esclusione / stato | S4: Contributo num. tema 1 | T4: Contributo den. tema 1 | U4: Contributo num. tema 2 | V4: Contributo den. tema 2 | W4: Note controllo
A5: 2 | B5: 1 | C5: CQ1 | D5: CULTURA | E5: CULTURA E COMPORTAMENTI | F5: MAT | I5: =IF(G5="","",IFERROR(VLOOKUP(G5,'Note e assunzioni'!$A$23:$B$32,2,FALSE),"Codice non mappato")) | J5: =IF(Q5="Sì",IF(H5="",1,0.7),0) -> 0 | K5: =IF(H5="","",IFERROR(VLOOKUP(H5,'Note e assunzioni'!$A$23:$B$32,2,FALSE),"Codice non mappato")) | L5: =IF(Q5="Sì",IF(H5="",0,0.3),0) -> 0 | M5: 1 | N5: 1 | O5: =IFERROR(INDEX('Input survey A'!$C$12:$C$67,MATCH(C5,'Input survey A'!$A$12:$A$67,0)),"") -> 3 | Q5: =IF(F5="MAT","No",IF(G5="","No",IF(M5="","No",IF(OR(NOT(ISNUMBER(O5)),O5<1,O5>4),"No","Sì")))) -> No | R5: =IF(F5="MAT","MAT - esclusa dal calcolo matrice",IF(G5="","Cod. 1 assente",IF(M5="","Peso PMI assente/non numerico",IF(NOT(ISNUMBER(O5)),"Risposta assente/non numerica",IF(OR(O5<1,O5>4),"Risposta fuori scala","Inclusa"))))) -> MAT - esclusa dal calcolo matrice | S5: =IF(Q5="Sì",O5*M5*J5,0) -> 0 | T5: =IF(Q5="Sì",M5*J5,0) -> 0 | U5: =IF(Q5="Sì",O5*M5*L5,0) -> 0 | V5: =IF(Q5="Sì",M5*L5,0) -> 0
A6: 3 | B6: 2 | C6: CQ2 | D6: CULTURA | E6: CULTURA E COMPORTAMENTI | F6: EE | G6: EE | I6: =IF(G6="","",IFERROR(VLOOKUP(G6,'Note e assunzioni'!$A$23:$B$32,2,FALSE),"Codice non mappato")) -> Employees Engagement | J6: =IF(Q6="Sì",IF(H6="",1,0.7),0) -> 1 | K6: =IF(H6="","",IFERROR(VLOOKUP(H6,'Note e assunzioni'!$A$23:$B$32,2,FALSE),"Codice non mappato")) | L6: =IF(Q6="Sì",IF(H6="",0,0.3),0) -> 0 | M6: 3 | N6: 2.5 | O6: =IFERROR(INDEX('Input survey A'!$C$12:$C$67,MATCH(C6,'Input survey A'!$A$12:$A$67,0)),"") -> 1 | Q6: =IF(F6="MAT","No",IF(G6="","No",IF(M6="","No",IF(OR(NOT(ISNUMBER(O6)),O6<1,O6>4),"No","Sì")))) -> Sì | R6: =IF(F6="MAT","MAT - esclusa dal calcolo matrice",IF(G6="","Cod. 1 assente",IF(M6="","Peso PMI assente/non numerico",IF(NOT(ISNUMBER(O6)),"Risposta assente/non numerica",IF(OR(O6<1,O6>4),"Risposta fuori scala","Inclusa"))))) -> Inclusa | S6: =IF(Q6="Sì",O6*M6*J6,0) -> 3 | T6: =IF(Q6="Sì",M6*J6,0) -> 3 | U6: =IF(Q6="Sì",O6*M6*L6,0) -> 0 | V6: =IF(Q6="Sì",M6*L6,0) -> 0
A7: 4 | B7: 3 | C7: CQ3 | D7: CULTURA | E7: CULTURA E COMPORTAMENTI | F7: EE/ND | G7: EE | H7: ND | I7: =IF(G7="","",IFERROR(VLOOKUP(G7,'Note e assunzioni'!$A$23:$B$32,2,FALSE),"Codice non mappato")) -> Employees Engagement | J7: =IF(Q7="Sì",IF(H7="",1,0.7),0) -> 0.7 | K7: =IF(H7="","",IFERROR(VLOOKUP(H7,'Note e assunzioni'!$A$23:$B$32,2,FALSE),"Codice non mappato")) -> Non-discrimination | L7: =IF(Q7="Sì",IF(H7="",0,0.3),0) -> 0.3 | M7: 3 | N7: 2 | O7: =IFERROR(INDEX('Input survey A'!$C$12:$C$67,MATCH(C7,'Input survey A'!$A$12:$A$67,0)),"") -> 3 | Q7: =IF(F7="MAT","No",IF(G7="","No",IF(M7="","No",IF(OR(NOT(ISNUMBER(O7)),O7<1,O7>4),"No","Sì")))) -> Sì | R7: =IF(F7="MAT","MAT - esclusa dal calcolo matrice",IF(G7="","Cod. 1 assente",IF(M7="","Peso PMI assente/non numerico",IF(NOT(ISNUMBER(O7)),"Risposta assente/non numerica",IF(OR(O7<1,O7>4),"Risposta fuori scala","Inclusa"))))) -> Inclusa | S7: =IF(Q7="Sì",O7*M7*J7,0) -> 6.3 | T7: =IF(Q7="Sì",M7*J7,0) -> 2.1 | U7: =IF(Q7="Sì",O7*M7*L7,0) -> 2.7 | V7: =IF(Q7="Sì",M7*L7,0) -> 0.9
A8: 5 | B8: 4 | C8: CQ4 | D8: CULTURA | E8: BENESSERE E SICUREZZA PSICOLOGICA | F8: ND | G8: ND | I8: =IF(G8="","",IFERROR(VLOOKUP(G8,'Note e assunzioni'!$A$23:$B$32,2,FALSE),"Codice non mappato")) -> Non-discrimination | J8: =IF(Q8="Sì",IF(H8="",1,0.7),0) -> 1 | K8: =IF(H8="","",IFERROR(VLOOKUP(H8,'Note e assunzioni'!$A$23:$B$32,2,FALSE),"Codice non mappato")) | L8: =IF(Q8="Sì",IF(H8="",0,0.3),0) -> 0 | M8: 1 | N8: 1 | O8: =IFERROR(INDEX('Input survey A'!$C$12:$C$67,MATCH(C8,'Input survey A'!$A$12:$A$67,0)),"") -> 2 | Q8: =IF(F8="MAT","No",IF(G8="","No",IF(M8="","No",IF(OR(NOT(ISNUMBER(O8)),O8<1,O8>4),"No","Sì")))) -> Sì | R8: =IF(F8="MAT","MAT - esclusa dal calcolo matrice",IF(G8="","Cod. 1 assente",IF(M8="","Peso PMI assente/non numerico",IF(NOT(ISNUMBER(O8)),"Risposta assente/non numerica",IF(OR(O8<1,O8>4),"Risposta fuori scala","Inclusa"))))) -> Inclusa | S8: =IF(Q8="Sì",O8*M8*J8,0) -> 2 | T8: =IF(Q8="Sì",M8*J8,0) -> 1 | U8: =IF(Q8="Sì",O8*M8*L8,0) -> 0 | V8: =IF(Q8="Sì",M8*L8,0) -> 0
A9: 6 | B9: 5 | C9: CQ5 | D9: CULTURA | E9: BENESSERE E SICUREZZA PSICOLOGICA | F9: MAT | I9: =IF(G9="","",IFERROR(VLOOKUP(G9,'Note e assunzioni'!$A$23:$B$32,2,FALSE),"Codice non mappato")) | J9: =IF(Q9="Sì",IF(H9="",1,0.7),0) -> 0 | K9: =IF(H9="","",IFERROR(VLOOKUP(H9,'Note e assunzioni'!$A$23:$B$32,2,FALSE),"Codice non mappato")) | L9: =IF(Q9="Sì",IF(H9="",0,0.3),0) -> 0 | M9: 2.5 | N9: 1.5 | O9: =IFERROR(INDEX('Input survey A'!$C$12:$C$67,MATCH(C9,'Input survey A'!$A$12:$A$67,0)),"") -> 4 | Q9: =IF(F9="MAT","No",IF(G9="","No",IF(M9="","No",IF(OR(NOT(ISNUMBER(O9)),O9<1,O9>4),"No","Sì")))) -> No | R9: =IF(F9="MAT","MAT - esclusa dal calcolo matrice",IF(G9="","Cod. 1 assente",IF(M9="","Peso PMI assente/non numerico",IF(NOT(ISNUMBER(O9)),"Risposta assente/non numerica",IF(OR(O9<1,O9>4),"Risposta fuori scala","Inclusa"))))) -> MAT - esclusa dal calcolo matrice | S9: =IF(Q9="Sì",O9*M9*J9,0) -> 0 | T9: =IF(Q9="Sì",M9*J9,0) -> 0 | U9: =IF(Q9="Sì",O9*M9*L9,0) -> 0 | V9: =IF(Q9="Sì",M9*L9,0) -> 0
A10: 7 | B10: 6 | C10: PQ1 | D10: PROCESSI | E10: PROCESSI OPERATIVI E ACCESSIBILITÀ | F10: EE | G10: EE | I10: =IF(G10="","",IFERROR(VLOOKUP(G10,'Note e assunzioni'!$A$23:$B$32,2,FALSE),"Codice non mappato")) -> Employees Engagement | J10: =IF(Q10="Sì",IF(H10="",1,0.7),0) -> 1 | K10: =IF(H10="","",IFERROR(VLOOKUP(H10,'Note e assunzioni'!$A$23:$B$32,2,FALSE),"Codice non mappato")) | L10: =IF(Q10="Sì",IF(H10="",0,0.3),0) -> 0 | M10: 1.5 | N10: 1 | O10: =IFERROR(INDEX('Input survey A'!$C$12:$C$67,MATCH(C10,'Input survey A'!$A$12:$A$67,0)),"") -> 2 | Q10: =IF(F10="MAT","No",IF(G10="","No",IF(M10="","No",IF(OR(NOT(ISNUMBER(O10)),O10<1,O10>4),"No","Sì")))) -> Sì | R10: =IF(F10="MAT","MAT - esclusa dal calcolo matrice",IF(G10="","Cod. 1 assente",IF(M10="","Peso PMI assente/non numerico",IF(NOT(ISNUMBER(O10)),"Risposta assente/non numerica",IF(OR(O10<1,O10>4),"Risposta fuori scala","Inclusa"))))) -> Inclusa | S10: =IF(Q10="Sì",O10*M10*J10,0) -> 3 | T10: =IF(Q10="Sì",M10*J10,0) -> 1.5 | U10: =IF(Q10="Sì",O10*M10*L10,0) -> 0 | V10: =IF(Q10="Sì",M10*L10,0) -> 0
A11: 8 | B11: 7 | C11: PQ2 | D11: PROCESSI | E11: PERSONE E PROCESSI | F11: ET1/ET2 | G11: ET | I11: =IF(G11="","",IFERROR(VLOOKUP(G11,'Note e assunzioni'!$A$23:$B$32,2,FALSE),"Codice non mappato")) -> Education & Training | J11: =IF(Q11="Sì",IF(H11="",1,0.7),0) -> 1 | K11: =IF(H11="","",IFERROR(VLOOKUP(H11,'Note e assunzioni'!$A$23:$B$32,2,FALSE),"Codice non mappato")) | L11: =IF(Q11="Sì",IF(H11="",0,0.3),0) -> 0 | M11: 2.5 | N11: 1.5 | O11: =IFERROR(INDEX('Input survey A'!$C$12:$C$67,MATCH(C11,'Input survey A'!$A$12:$A$67,0)),"") -> 2 | Q11: =IF(F11="MAT","No",IF(G11="","No",IF(M11="","No",IF(OR(NOT(ISNUMBER(O11)),O11<1,O11>4),"No","Sì")))) -> Sì | R11: =IF(F11="MAT","MAT - esclusa dal calcolo matrice",IF(G11="","Cod. 1 assente",IF(M11="","Peso PMI assente/non numerico",IF(NOT(ISNUMBER(O11)),"Risposta assente/non numerica",IF(OR(O11<1,O11>4),"Risposta fuori scala","Inclusa"))))) -> Inclusa | S11: =IF(Q11="Sì",O11*M11*J11,0) -> 5 | T11: =IF(Q11="Sì",M11*J11,0) -> 2.5 | U11: =IF(Q11="Sì",O11*M11*L11,0) -> 0 | V11: =IF(Q11="Sì",M11*L11,0) -> 0
A12: 9 | B12: 8 | C12: PQ3 | D12: PROCESSI | E12: PERSONE E PROCESSI | F12: E2 | G12: E | I12: =IF(G12="","",IFERROR(VLOOKUP(G12,'Note e assunzioni'!$A$23:$B$32,2,FALSE),"Codice non mappato")) -> Employment | J12: =IF(Q12="Sì",IF(H12="",1,0.7),0) -> 1 | K12: =IF(H12="","",IFERROR(VLOOKUP(H12,'Note e assunzioni'!$A$23:$B$32,2,FALSE),"Codice non mappato")) | L12: =IF(Q12="Sì",IF(H12="",0,0.3),0) -> 0 | M12: 1 | N12: 1 | O12: =IFERROR(INDEX('Input survey A'!$C$12:$C$67,MATCH(C12,'Input survey A'!$A$12:$A$67,0)),"") -> 3 | Q12: =IF(F12="MAT","No",IF(G12="","No",IF(M12="","No",IF(OR(NOT(ISNUMBER(O12)),O12<1,O12>4),"No","Sì")))) -> Sì | R12: =IF(F12="MAT","MAT - esclusa dal calcolo matrice",IF(G12="","Cod. 1 assente",IF(M12="","Peso PMI assente/non numerico",IF(NOT(ISNUMBER(O12)),"Risposta assente/non numerica",IF(OR(O12<1,O12>4),"Risposta fuori scala","Inclusa"))))) -> Inclusa | S12: =IF(Q12="Sì",O12*M12*J12,0) -> 3 | T12: =IF(Q12="Sì",M12*J12,0) -> 1 | U12: =IF(Q12="Sì",O12*M12*L12,0) -> 0 | V12: =IF(Q12="Sì",M12*L12,0) -> 0
A13: 10 | B13: 9 | C13: PQ4 | D13: PROCESSI | E13: PERSONE E PROCESSI | F13: E3 | G13: E | I13: =IF(G13="","",IFERROR(VLOOKUP(G13,'Note e assunzioni'!$A$23:$B$32,2,FALSE),"Codice non mappato")) -> Employment | J13: =IF(Q13="Sì",IF(H13="",1,0.7),0) -> 1 | K13: =IF(H13="","",IFERROR(VLOOKUP(H13,'Note e assunzioni'!$A$23:$B$32,2,FALSE),"Codice non mappato")) | L13: =IF(Q13="Sì",IF(H13="",0,0.3),0) -> 0 | M13: 3 | N13: 2 | O13: =IFERROR(INDEX('Input survey A'!$C$12:$C$67,MATCH(C13,'Input survey A'!$A$12:$A$67,0)),"") -> 1 | Q13: =IF(F13="MAT","No",IF(G13="","No",IF(M13="","No",IF(OR(NOT(ISNUMBER(O13)),O13<1,O13>4),"No","Sì")))) -> Sì | R13: =IF(F13="MAT","MAT - esclusa dal calcolo matrice",IF(G13="","Cod. 1 assente",IF(M13="","Peso PMI assente/non numerico",IF(NOT(ISNUMBER(O13)),"Risposta assente/non numerica",IF(OR(O13<1,O13>4),"Risposta fuori scala","Inclusa"))))) -> Inclusa | S13: =IF(Q13="Sì",O13*M13*J13,0) -> 3 | T13: =IF(Q13="Sì",M13*J13,0) -> 3 | U13: =IF(Q13="Sì",O13*M13*L13,0) -> 0 | V13: =IF(Q13="Sì",M13*L13,0) -> 0
A14: 11 | B14: 10 | C14: PQ5 | D14: PROCESSI | E14: PERSONE E PROCESSI | F14: E1/E2 | G14: E | I14: =IF(G14="","",IFERROR(VLOOKUP(G14,'Note e assunzioni'!$A$23:$B$32,2,FALSE),"Codice non mappato")) -> Employment | J14: =IF(Q14="Sì",IF(H14="",1,0.7),0) -> 1 | K14: =IF(H14="","",IFERROR(VLOOKUP(H14,'Note e assunzioni'!$A$23:$B$32,2,FALSE),"Codice non mappato")) | L14: =IF(Q14="Sì",IF(H14="",0,0.3),0) -> 0 | M14: 3 | N14: 3 | O14: =IFERROR(INDEX('Input survey A'!$C$12:$C$67,MATCH(C14,'Input survey A'!$A$12:$A$67,0)),"") -> 2 | Q14: =IF(F14="MAT","No",IF(G14="","No",IF(M14="","No",IF(OR(NOT(ISNUMBER(O14)),O14<1,O14>4),"No","Sì")))) -> Sì | R14: =IF(F14="MAT","MAT - esclusa dal calcolo matrice",IF(G14="","Cod. 1 assente",IF(M14="","Peso PMI assente/non numerico",IF(NOT(ISNUMBER(O14)),"Risposta assente/non numerica",IF(OR(O14<1,O14>4),"Risposta fuori scala","Inclusa"))))) -> Inclusa | S14: =IF(Q14="Sì",O14*M14*J14,0) -> 6 | T14: =IF(Q14="Sì",M14*J14,0) -> 3 | U14: =IF(Q14="Sì",O14*M14*L14,0) -> 0 | V14: =IF(Q14="Sì",M14*L14,0) -> 0
A15: 12 | B15: 11 | C15: PQ6 | D15: PROCESSI | E15: PERSONE E PROCESSI | F15: HR1/HR2 | G15: HR | I15: =IF(G15="","",IFERROR(VLOOKUP(G15,'Note e assunzioni'!$A$23:$B$32,2,FALSE),"Codice non mappato")) -> HR | J15: =IF(Q15="Sì",IF(H15="",1,0.7),0) -> 1 | K15: =IF(H15="","",IFERROR(VLOOKUP(H15,'Note e assunzioni'!$A$23:$B$32,2,FALSE),"Codice non mappato")) | L15: =IF(Q15="Sì",IF(H15="",0,0.3),0) -> 0 | M15: 2 | N15: 1 | O15: =IFERROR(INDEX('Input survey A'!$C$12:$C$67,MATCH(C15,'Input survey A'!$A$12:$A$67,0)),"") -> 2 | Q15: =IF(F15="MAT","No",IF(G15="","No",IF(M15="","No",IF(OR(NOT(ISNUMBER(O15)),O15<1,O15>4),"No","Sì")))) -> Sì | R15: =IF(F15="MAT","MAT - esclusa dal calcolo matrice",IF(G15="","Cod. 1 assente",IF(M15="","Peso PMI assente/non numerico",IF(NOT(ISNUMBER(O15)),"Risposta assente/non numerica",IF(OR(O15<1,O15>4),"Risposta fuori scala","Inclusa"))))) -> Inclusa | S15: =IF(Q15="Sì",O15*M15*J15,0) -> 4 | T15: =IF(Q15="Sì",M15*J15,0) -> 2 | U15: =IF(Q15="Sì",O15*M15*L15,0) -> 0 | V15: =IF(Q15="Sì",M15*L15,0) -> 0
A16: 13 | B16: 12 | C16: PQ7 | D16: PROCESSI | E16: PERSONE E PROCESSI | F16: ET1/ET4 | G16: ET | I16: =IF(G16="","",IFERROR(VLOOKUP(G16,'Note e assunzioni'!$A$23:$B$32,2,FALSE),"Codice non mappato")) -> Education & Training | J16: =IF(Q16="Sì",IF(H16="",1,0.7),0) -> 1 | K16: =IF(H16="","",IFERROR(VLOOKUP(H16,'Note e assunzioni'!$A$23:$B$32,2,FALSE),"Codice non mappato")) | L16: =IF(Q16="Sì",IF(H16="",0,0.3),0) -> 0 | M16: 2 | N16: 1.5 | O16: =IFERROR(INDEX('Input survey A'!$C$12:$C$67,MATCH(C16,'Input survey A'!$A$12:$A$67,0)),"") -> 1 | Q16: =IF(F16="MAT","No",IF(G16="","No",IF(M16="","No",IF(OR(NOT(ISNUMBER(O16)),O16<1,O16>4),"No","Sì")))) -> Sì | R16: =IF(F16="MAT","MAT - esclusa dal calcolo matrice",IF(G16="","Cod. 1 assente",IF(M16="","Peso PMI assente/non numerico",IF(NOT(ISNUMBER(O16)),"Risposta assente/non numerica",IF(OR(O16<1,O16>4),"Risposta fuori scala","Inclusa"))))) -> Inclusa | S16: =IF(Q16="Sì",O16*M16*J16,0) -> 2 | T16: =IF(Q16="Sì",M16*J16,0) -> 2 | U16: =IF(Q16="Sì",O16*M16*L16,0) -> 0 | V16: =IF(Q16="Sì",M16*L16,0) -> 0
A17: 14 | B17: 13 | C17: CQ6 | D17: CULTURA | E17: FORMAZIONE E CONSAPEVOLEZZA | F17: ET2/ET3 | G17: ET | I17: =IF(G17="","",IFERROR(VLOOKUP(G17,'Note e assunzioni'!$A$23:$B$32,2,FALSE),"Codice non mappato")) -> Education & Training | J17: =IF(Q17="Sì",IF(H17="",1,0.7),0) -> 1 | K17: =IF(H17="","",IFERROR(VLOOKUP(H17,'Note e assunzioni'!$A$23:$B$32,2,FALSE),"Codice non mappato")) | L17: =IF(Q17="Sì",IF(H17="",0,0.3),0) -> 0 | M17: 3 | N17: 1.5 | O17: =IFERROR(INDEX('Input survey A'!$C$12:$C$67,MATCH(C17,'Input survey A'!$A$12:$A$67,0)),"") -> 2 | Q17: =IF(F17="MAT","No",IF(G17="","No",IF(M17="","No",IF(OR(NOT(ISNUMBER(O17)),O17<1,O17>4),"No","Sì")))) -> Sì | R17: =IF(F17="MAT","MAT - esclusa dal calcolo matrice",IF(G17="","Cod. 1 assente",IF(M17="","Peso PMI assente/non numerico",IF(NOT(ISNUMBER(O17)),"Risposta assente/non numerica",IF(OR(O17<1,O17>4),"Risposta fuori scala","Inclusa"))))) -> Inclusa | S17: =IF(Q17="Sì",O17*M17*J17,0) -> 6 | T17: =IF(Q17="Sì",M17*J17,0) -> 3 | U17: =IF(Q17="Sì",O17*M17*L17,0) -> 0 | V17: =IF(Q17="Sì",M17*L17,0) -> 0
A18: 15 | B18: 14 | C18: PQ8 | D18: PROCESSI | E18: PERSONE E PROCESSI | F18: HR2/E1 | G18: HR | H18: E | I18: =IF(G18="","",IFERROR(VLOOKUP(G18,'Note e assunzioni'!$A$23:$B$32,2,FALSE),"Codice non mappato")) -> HR | J18: =IF(Q18="Sì",IF(H18="",1,0.7),0) -> 0.7 | K18: =IF(H18="","",IFERROR(VLOOKUP(H18,'Note e assunzioni'!$A$23:$B$32,2,FALSE),"Codice non mappato")) -> Employment | L18: =IF(Q18="Sì",IF(H18="",0,0.3),0) -> 0.3 | M18: 2.5 | N18: 1.5 | O18: =IFERROR(INDEX('Input survey A'!$C$12:$C$67,MATCH(C18,'Input survey A'!$A$12:$A$67,0)),"") -> 4 | Q18: =IF(F18="MAT","No",IF(G18="","No",IF(M18="","No",IF(OR(NOT(ISNUMBER(O18)),O18<1,O18>4),"No","Sì")))) -> Sì | R18: =IF(F18="MAT","MAT - esclusa dal calcolo matrice",IF(G18="","Cod. 1 assente",IF(M18="","Peso PMI assente/non numerico",IF(NOT(ISNUMBER(O18)),"Risposta assente/non numerica",IF(OR(O18<1,O18>4),"Risposta fuori scala","Inclusa"))))) -> Inclusa | S18: =IF(Q18="Sì",O18*M18*J18,0) -> 7 | T18: =IF(Q18="Sì",M18*J18,0) -> 1.75 | U18: =IF(Q18="Sì",O18*M18*L18,0) -> 3 | V18: =IF(Q18="Sì",M18*L18,0) -> 0.75
A19: 16 | B19: 15 | C19: PQ9 | D19: PROCESSI | E19: PERSONE E PROCESSI | F19: HR2/E1 | G19: HR | H19: E | I19: =IF(G19="","",IFERROR(VLOOKUP(G19,'Note e assunzioni'!$A$23:$B$32,2,FALSE),"Codice non mappato")) -> HR | J19: =IF(Q19="Sì",IF(H19="",1,0.7),0) -> 0.7 | K19: =IF(H19="","",IFERROR(VLOOKUP(H19,'Note e assunzioni'!$A$23:$B$32,2,FALSE),"Codice non mappato")) -> Employment | L19: =IF(Q19="Sì",IF(H19="",0,0.3),0) -> 0.3 | M19: 2.5 | N19: 1.5 | O19: =IFERROR(INDEX('Input survey A'!$C$12:$C$67,MATCH(C19,'Input survey A'!$A$12:$A$67,0)),"") -> 3 | Q19: =IF(F19="MAT","No",IF(G19="","No",IF(M19="","No",IF(OR(NOT(ISNUMBER(O19)),O19<1,O19>4),"No","Sì")))) -> Sì | R19: =IF(F19="MAT","MAT - esclusa dal calcolo matrice",IF(G19="","Cod. 1 assente",IF(M19="","Peso PMI assente/non numerico",IF(NOT(ISNUMBER(O19)),"Risposta assente/non numerica",IF(OR(O19<1,O19>4),"Risposta fuori scala","Inclusa"))))) -> Inclusa | S19: =IF(Q19="Sì",O19*M19*J19,0) -> 5.25 | T19: =IF(Q19="Sì",M19*J19,0) -> 1.75 | U19: =IF(Q19="Sì",O19*M19*L19,0) -> 2.25 | V19: =IF(Q19="Sì",M19*L19,0) -> 0.75
A20: 17 | B20: 16 | C20: PQ10 | D20: PROCESSI | E20: PERSONE E PROCESSI | F20: M/HR1 | G20: M | H20: HR | I20: =IF(G20="","",IFERROR(VLOOKUP(G20,'Note e assunzioni'!$A$23:$B$32,2,FALSE),"Codice non mappato")) -> Monitoring | J20: =IF(Q20="Sì",IF(H20="",1,0.7),0) -> 0.7 | K20: =IF(H20="","",IFERROR(VLOOKUP(H20,'Note e assunzioni'!$A$23:$B$32,2,FALSE),"Codice non mappato")) -> HR | L20: =IF(Q20="Sì",IF(H20="",0,0.3),0) -> 0.3 | M20: 3 | N20: 1.5 | O20: =IFERROR(INDEX('Input survey A'!$C$12:$C$67,MATCH(C20,'Input survey A'!$A$12:$A$67,0)),"") -> 2 | Q20: =IF(F20="MAT","No",IF(G20="","No",IF(M20="","No",IF(OR(NOT(ISNUMBER(O20)),O20<1,O20>4),"No","Sì")))) -> Sì | R20: =IF(F20="MAT","MAT - esclusa dal calcolo matrice",IF(G20="","Cod. 1 assente",IF(M20="","Peso PMI assente/non numerico",IF(NOT(ISNUMBER(O20)),"Risposta assente/non numerica",IF(OR(O20<1,O20>4),"Risposta fuori scala","Inclusa"))))) -> Inclusa | S20: =IF(Q20="Sì",O20*M20*J20,0) -> 4.2 | T20: =IF(Q20="Sì",M20*J20,0) -> 2.1 | U20: =IF(Q20="Sì",O20*M20*L20,0) -> 1.8 | V20: =IF(Q20="Sì",M20*L20,0) -> 0.9
A21: 18 | B21: 17 | C21: PQ11 | D21: PROCESSI | E21: PERSONE E PROCESSI | F21: E2/E4 | G21: E | I21: =IF(G21="","",IFERROR(VLOOKUP(G21,'Note e assunzioni'!$A$23:$B$32,2,FALSE),"Codice non mappato")) -> Employment | J21: =IF(Q21="Sì",IF(H21="",1,0.7),0) -> 1 | K21: =IF(H21="","",IFERROR(VLOOKUP(H21,'Note e assunzioni'!$A$23:$B$32,2,FALSE),"Codice non mappato")) | L21: =IF(Q21="Sì",IF(H21="",0,0.3),0) -> 0 | M21: 1.5 | N21: 1 | O21: =IFERROR(INDEX('Input survey A'!$C$12:$C$67,MATCH(C21,'Input survey A'!$A$12:$A$67,0)),"") -> 2 | Q21: =IF(F21="MAT","No",IF(G21="","No",IF(M21="","No",IF(OR(NOT(ISNUMBER(O21)),O21<1,O21>4),"No","Sì")))) -> Sì | R21: =IF(F21="MAT","MAT - esclusa dal calcolo matrice",IF(G21="","Cod. 1 assente",IF(M21="","Peso PMI assente/non numerico",IF(NOT(ISNUMBER(O21)),"Risposta assente/non numerica",IF(OR(O21<1,O21>4),"Risposta fuori scala","Inclusa"))))) -> Inclusa | S21: =IF(Q21="Sì",O21*M21*J21,0) -> 3 | T21: =IF(Q21="Sì",M21*J21,0) -> 1.5 | U21: =IF(Q21="Sì",O21*M21*L21,0) -> 0 | V21: =IF(Q21="Sì",M21*L21,0) -> 0
A22: 19 | B22: 18 | C22: PQ12 | D22: PROCESSI | E22: PROCESSI OPERATIVI E ACCESSIBILITÀ | F22: E1/ND | G22: E | H22: ND | I22: =IF(G22="","",IFERROR(VLOOKUP(G22,'Note e assunzioni'!$A$23:$B$32,2,FALSE),"Codice non mappato")) -> Employment | J22: =IF(Q22="Sì",IF(H22="",1,0.7),0) -> 0.7 | K22: =IF(H22="","",IFERROR(VLOOKUP(H22,'Note e assunzioni'!$A$23:$B$32,2,FALSE),"Codice non mappato")) -> Non-discrimination | L22: =IF(Q22="Sì",IF(H22="",0,0.3),0) -> 0.3 | M22: 3 | N22: 2 | O22: =IFERROR(INDEX('Input survey A'!$C$12:$C$67,MATCH(C22,'Input survey A'!$A$12:$A$67,0)),"") -> 2 | Q22: =IF(F22="MAT","No",IF(G22="","No",IF(M22="","No",IF(OR(NOT(ISNUMBER(O22)),O22<1,O22>4),"No","Sì")))) -> Sì | R22: =IF(F22="MAT","MAT - esclusa dal calcolo matrice",IF(G22="","Cod. 1 assente",IF(M22="","Peso PMI assente/non numerico",IF(NOT(ISNUMBER(O22)),"Risposta assente/non numerica",IF(OR(O22<1,O22>4),"Risposta fuori scala","Inclusa"))))) -> Inclusa | S22: =IF(Q22="Sì",O22*M22*J22,0) -> 4.2 | T22: =IF(Q22="Sì",M22*J22,0) -> 2.1 | U22: =IF(Q22="Sì",O22*M22*L22,0) -> 1.8 | V22: =IF(Q22="Sì",M22*L22,0) -> 0.9
A23: 20 | B23: 19 | C23: SQ1 | D23: STRATEGIA | E23: STRATEGIA E PIANIFICAZIONE | F23: F | G23: F | I23: =IF(G23="","",IFERROR(VLOOKUP(G23,'Note e assunzioni'!$A$23:$B$32,2,FALSE),"Codice non mappato")) -> Foundation | J23: =IF(Q23="Sì",IF(H23="",1,0.7),0) -> 1 | K23: =IF(H23="","",IFERROR(VLOOKUP(H23,'Note e assunzioni'!$A$23:$B$32,2,FALSE),"Codice non mappato")) | L23: =IF(Q23="Sì",IF(H23="",0,0.3),0) -> 0 | M23: 1.5 | N23: 1 | O23: =IFERROR(INDEX('Input survey A'!$C$12:$C$67,MATCH(C23,'Input survey A'!$A$12:$A$67,0)),"") -> 2 | Q23: =IF(F23="MAT","No",IF(G23="","No",IF(M23="","No",IF(OR(NOT(ISNUMBER(O23)),O23<1,O23>4),"No","Sì")))) -> Sì | R23: =IF(F23="MAT","MAT - esclusa dal calcolo matrice",IF(G23="","Cod. 1 assente",IF(M23="","Peso PMI assente/non numerico",IF(NOT(ISNUMBER(O23)),"Risposta assente/non numerica",IF(OR(O23<1,O23>4),"Risposta fuori scala","Inclusa"))))) -> Inclusa | S23: =IF(Q23="Sì",O23*M23*J23,0) -> 3 | T23: =IF(Q23="Sì",M23*J23,0) -> 1.5 | U23: =IF(Q23="Sì",O23*M23*L23,0) -> 0 | V23: =IF(Q23="Sì",M23*L23,0) -> 0
A24: 21 | B24: 20 | C24: PQ13 | D24: PROCESSI | E24: PROCESSI OPERATIVI E ACCESSIBILITÀ | F24: E1 | G24: E | I24: =IF(G24="","",IFERROR(VLOOKUP(G24,'Note e assunzioni'!$A$23:$B$32,2,FALSE),"Codice non mappato")) -> Employment | J24: =IF(Q24="Sì",IF(H24="",1,0.7),0) -> 1 | K24: =IF(H24="","",IFERROR(VLOOKUP(H24,'Note e assunzioni'!$A$23:$B$32,2,FALSE),"Codice non mappato")) | L24: =IF(Q24="Sì",IF(H24="",0,0.3),0) -> 0 | M24: 1.5 | N24: 1 | O24: =IFERROR(INDEX('Input survey A'!$C$12:$C$67,MATCH(C24,'Input survey A'!$A$12:$A$67,0)),"") -> 2 | Q24: =IF(F24="MAT","No",IF(G24="","No",IF(M24="","No",IF(OR(NOT(ISNUMBER(O24)),O24<1,O24>4),"No","Sì")))) -> Sì | R24: =IF(F24="MAT","MAT - esclusa dal calcolo matrice",IF(G24="","Cod. 1 assente",IF(M24="","Peso PMI assente/non numerico",IF(NOT(ISNUMBER(O24)),"Risposta assente/non numerica",IF(OR(O24<1,O24>4),"Risposta fuori scala","Inclusa"))))) -> Inclusa | S24: =IF(Q24="Sì",O24*M24*J24,0) -> 3 | T24: =IF(Q24="Sì",M24*J24,0) -> 1.5 | U24: =IF(Q24="Sì",O24*M24*L24,0) -> 0 | V24: =IF(Q24="Sì",M24*L24,0) -> 0
A25: 22 | B25: 21 | C25: PQ14 | D25: PROCESSI | E25: PROCESSI OPERATIVI E ACCESSIBILITÀ | F25: E1 | G25: E | I25: =IF(G25="","",IFERROR(VLOOKUP(G25,'Note e assunzioni'!$A$23:$B$32,2,FALSE),"Codice non mappato")) -> Employment | J25: =IF(Q25="Sì",IF(H25="",1,0.7),0) -> 1 | K25: =IF(H25="","",IFERROR(VLOOKUP(H25,'Note e assunzioni'!$A$23:$B$32,2,FALSE),"Codice non mappato")) | L25: =IF(Q25="Sì",IF(H25="",0,0.3),0) -> 0 | M25: 1.5 | N25: 1 | O25: =IFERROR(INDEX('Input survey A'!$C$12:$C$67,MATCH(C25,'Input survey A'!$A$12:$A$67,0)),"") -> 2 | Q25: =IF(F25="MAT","No",IF(G25="","No",IF(M25="","No",IF(OR(NOT(ISNUMBER(O25)),O25<1,O25>4),"No","Sì")))) -> Sì | R25: =IF(F25="MAT","MAT - esclusa dal calcolo matrice",IF(G25="","Cod. 1 assente",IF(M25="","Peso PMI assente/non numerico",IF(NOT(ISNUMBER(O25)),"Risposta assente/non numerica",IF(OR(O25<1,O25>4),"Risposta fuori scala","Inclusa"))))) -> Inclusa | S25: =IF(Q25="Sì",O25*M25*J25,0) -> 3 | T25: =IF(Q25="Sì",M25*J25,0) -> 1.5 | U25: =IF(Q25="Sì",O25*M25*L25,0) -> 0 | V25: =IF(Q25="Sì",M25*L25,0) -> 0
A26: 23 | B26: 22 | C26: PQ15 | D26: PROCESSI | E26: PROCESSI OPERATIVI E ACCESSIBILITÀ | F26: E1 | G26: E | I26: =IF(G26="","",IFERROR(VLOOKUP(G26,'Note e assunzioni'!$A$23:$B$32,2,FALSE),"Codice non mappato")) -> Employment | J26: =IF(Q26="Sì",IF(H26="",1,0.7),0) -> 1 | K26: =IF(H26="","",IFERROR(VLOOKUP(H26,'Note e assunzioni'!$A$23:$B$32,2,FALSE),"Codice non mappato")) | L26: =IF(Q26="Sì",IF(H26="",0,0.3),0) -> 0 | M26: 1.5 | N26: 1 | O26: =IFERROR(INDEX('Input survey A'!$C$12:$C$67,MATCH(C26,'Input survey A'!$A$12:$A$67,0)),"") -> 1 | Q26: =IF(F26="MAT","No",IF(G26="","No",IF(M26="","No",IF(OR(NOT(ISNUMBER(O26)),O26<1,O26>4),"No","Sì")))) -> Sì | R26: =IF(F26="MAT","MAT - esclusa dal calcolo matrice",IF(G26="","Cod. 1 assente",IF(M26="","Peso PMI assente/non numerico",IF(NOT(ISNUMBER(O26)),"Risposta assente/non numerica",IF(OR(O26<1,O26>4),"Risposta fuori scala","Inclusa"))))) -> Inclusa | S26: =IF(Q26="Sì",O26*M26*J26,0) -> 1.5 | T26: =IF(Q26="Sì",M26*J26,0) -> 1.5 | U26: =IF(Q26="Sì",O26*M26*L26,0) -> 0 | V26: =IF(Q26="Sì",M26*L26,0) -> 0
A27: 24 | B27: 23 | C27: PQ16 | D27: PROCESSI | E27: PROCESSI OPERATIVI E ACCESSIBILITÀ | F27: ND | G27: ND | I27: =IF(G27="","",IFERROR(VLOOKUP(G27,'Note e assunzioni'!$A$23:$B$32,2,FALSE),"Codice non mappato")) -> Non-discrimination | J27: =IF(Q27="Sì",IF(H27="",1,0.7),0) -> 1 | K27: =IF(H27="","",IFERROR(VLOOKUP(H27,'Note e assunzioni'!$A$23:$B$32,2,FALSE),"Codice non mappato")) | L27: =IF(Q27="Sì",IF(H27="",0,0.3),0) -> 0 | M27: 3 | N27: 2 | O27: =IFERROR(INDEX('Input survey A'!$C$12:$C$67,MATCH(C27,'Input survey A'!$A$12:$A$67,0)),"") -> 1 | Q27: =IF(F27="MAT","No",IF(G27="","No",IF(M27="","No",IF(OR(NOT(ISNUMBER(O27)),O27<1,O27>4),"No","Sì")))) -> Sì | R27: =IF(F27="MAT","MAT - esclusa dal calcolo matrice",IF(G27="","Cod. 1 assente",IF(M27="","Peso PMI assente/non numerico",IF(NOT(ISNUMBER(O27)),"Risposta assente/non numerica",IF(OR(O27<1,O27>4),"Risposta fuori scala","Inclusa"))))) -> Inclusa | S27: =IF(Q27="Sì",O27*M27*J27,0) -> 3 | T27: =IF(Q27="Sì",M27*J27,0) -> 3 | U27: =IF(Q27="Sì",O27*M27*L27,0) -> 0 | V27: =IF(Q27="Sì",M27*L27,0) -> 0
A28: 25 | B28: 24 | C28: SQ2 | D28: STRATEGIA | E28: GOVERNANCE E LEADERSHIP | F28: F | G28: F | I28: =IF(G28="","",IFERROR(VLOOKUP(G28,'Note e assunzioni'!$A$23:$B$32,2,FALSE),"Codice non mappato")) -> Foundation | J28: =IF(Q28="Sì",IF(H28="",1,0.7),0) -> 1 | K28: =IF(H28="","",IFERROR(VLOOKUP(H28,'Note e assunzioni'!$A$23:$B$32,2,FALSE),"Codice non mappato")) | L28: =IF(Q28="Sì",IF(H28="",0,0.3),0) -> 0 | M28: 2 | N28: 1 | O28: =IFERROR(INDEX('Input survey A'!$C$12:$C$67,MATCH(C28,'Input survey A'!$A$12:$A$67,0)),"") -> 2 | Q28: =IF(F28="MAT","No",IF(G28="","No",IF(M28="","No",IF(OR(NOT(ISNUMBER(O28)),O28<1,O28>4),"No","Sì")))) -> Sì | R28: =IF(F28="MAT","MAT - esclusa dal calcolo matrice",IF(G28="","Cod. 1 assente",IF(M28="","Peso PMI assente/non numerico",IF(NOT(ISNUMBER(O28)),"Risposta assente/non numerica",IF(OR(O28<1,O28>4),"Risposta fuori scala","Inclusa"))))) -> Inclusa | S28: =IF(Q28="Sì",O28*M28*J28,0) -> 4 | T28: =IF(Q28="Sì",M28*J28,0) -> 2 | U28: =IF(Q28="Sì",O28*M28*L28,0) -> 0 | V28: =IF(Q28="Sì",M28*L28,0) -> 0
A29: 26 | B29: 25 | C29: SQ3 | D29: STRATEGIA | E29: GOVERNANCE E LEADERSHIP | F29: ET2/F | G29: ET | H29: F | I29: =IF(G29="","",IFERROR(VLOOKUP(G29,'Note e assunzioni'!$A$23:$B$32,2,FALSE),"Codice non mappato")) -> Education & Training | J29: =IF(Q29="Sì",IF(H29="",1,0.7),0) -> 0.7 | K29: =IF(H29="","",IFERROR(VLOOKUP(H29,'Note e assunzioni'!$A$23:$B$32,2,FALSE),"Codice non mappato")) -> Foundation | L29: =IF(Q29="Sì",IF(H29="",0,0.3),0) -> 0.3 | M29: 3 | N29: 1.5 | O29: =IFERROR(INDEX('Input survey A'!$C$12:$C$67,MATCH(C29,'Input survey A'!$A$12:$A$67,0)),"") -> 2 | Q29: =IF(F29="MAT","No",IF(G29="","No",IF(M29="","No",IF(OR(NOT(ISNUMBER(O29)),O29<1,O29>4),"No","Sì")))) -> Sì | R29: =IF(F29="MAT","MAT - esclusa dal calcolo matrice",IF(G29="","Cod. 1 assente",IF(M29="","Peso PMI assente/non numerico",IF(NOT(ISNUMBER(O29)),"Risposta assente/non numerica",IF(OR(O29<1,O29>4),"Risposta fuori scala","Inclusa"))))) -> Inclusa | S29: =IF(Q29="Sì",O29*M29*J29,0) -> 4.2 | T29: =IF(Q29="Sì",M29*J29,0) -> 2.1 | U29: =IF(Q29="Sì",O29*M29*L29,0) -> 1.8 | V29: =IF(Q29="Sì",M29*L29,0) -> 0.9
A30: 27 | B30: 26 | C30: SQ4 | D30: STRATEGIA | E30: GOVERNANCE E LEADERSHIP | F30: MAT | I30: =IF(G30="","",IFERROR(VLOOKUP(G30,'Note e assunzioni'!$A$23:$B$32,2,FALSE),"Codice non mappato")) | J30: =IF(Q30="Sì",IF(H30="",1,0.7),0) -> 0 | K30: =IF(H30="","",IFERROR(VLOOKUP(H30,'Note e assunzioni'!$A$23:$B$32,2,FALSE),"Codice non mappato")) | L30: =IF(Q30="Sì",IF(H30="",0,0.3),0) -> 0 | M30: 1.5 | N30: 1 | O30: =IFERROR(INDEX('Input survey A'!$C$12:$C$67,MATCH(C30,'Input survey A'!$A$12:$A$67,0)),"") -> 2 | Q30: =IF(F30="MAT","No",IF(G30="","No",IF(M30="","No",IF(OR(NOT(ISNUMBER(O30)),O30<1,O30>4),"No","Sì")))) -> No | R30: =IF(F30="MAT","MAT - esclusa dal calcolo matrice",IF(G30="","Cod. 1 assente",IF(M30="","Peso PMI assente/non numerico",IF(NOT(ISNUMBER(O30)),"Risposta assente/non numerica",IF(OR(O30<1,O30>4),"Risposta fuori scala","Inclusa"))))) -> MAT - esclusa dal calcolo matrice | S30: =IF(Q30="Sì",O30*M30*J30,0) -> 0 | T30: =IF(Q30="Sì",M30*J30,0) -> 0 | U30: =IF(Q30="Sì",O30*M30*L30,0) -> 0 | V30: =IF(Q30="Sì",M30*L30,0) -> 0
A31: 28 | B31: 27 | C31: SQ5 | D31: STRATEGIA | E31: GOVERNANCE E LEADERSHIP | F31: M/F | G31: M | H31: F | I31: =IF(G31="","",IFERROR(VLOOKUP(G31,'Note e assunzioni'!$A$23:$B$32,2,FALSE),"Codice non mappato")) -> Monitoring | J31: =IF(Q31="Sì",IF(H31="",1,0.7),0) -> 0.7 | K31: =IF(H31="","",IFERROR(VLOOKUP(H31,'Note e assunzioni'!$A$23:$B$32,2,FALSE),"Codice non mappato")) -> Foundation | L31: =IF(Q31="Sì",IF(H31="",0,0.3),0) -> 0.3 | M31: 3 | N31: 1.5 | O31: =IFERROR(INDEX('Input survey A'!$C$12:$C$67,MATCH(C31,'Input survey A'!$A$12:$A$67,0)),"") -> 1 | Q31: =IF(F31="MAT","No",IF(G31="","No",IF(M31="","No",IF(OR(NOT(ISNUMBER(O31)),O31<1,O31>4),"No","Sì")))) -> Sì | R31: =IF(F31="MAT","MAT - esclusa dal calcolo matrice",IF(G31="","Cod. 1 assente",IF(M31="","Peso PMI assente/non numerico",IF(NOT(ISNUMBER(O31)),"Risposta assente/non numerica",IF(OR(O31<1,O31>4),"Risposta fuori scala","Inclusa"))))) -> Inclusa | S31: =IF(Q31="Sì",O31*M31*J31,0) -> 2.1 | T31: =IF(Q31="Sì",M31*J31,0) -> 2.1 | U31: =IF(Q31="Sì",O31*M31*L31,0) -> 0.9 | V31: =IF(Q31="Sì",M31*L31,0) -> 0.9
A32: 29 | B32: 28 | C32: SQ6 | D32: STRATEGIA | E32: GOVERNANCE E LEADERSHIP | F32: F | G32: F | I32: =IF(G32="","",IFERROR(VLOOKUP(G32,'Note e assunzioni'!$A$23:$B$32,2,FALSE),"Codice non mappato")) -> Foundation | J32: =IF(Q32="Sì",IF(H32="",1,0.7),0) -> 1 | K32: =IF(H32="","",IFERROR(VLOOKUP(H32,'Note e assunzioni'!$A$23:$B$32,2,FALSE),"Codice non mappato")) | L32: =IF(Q32="Sì",IF(H32="",0,0.3),0) -> 0 | M32: 2.5 | N32: 1.5 | O32: =IFERROR(INDEX('Input survey A'!$C$12:$C$67,MATCH(C32,'Input survey A'!$A$12:$A$67,0)),"") -> 2 | Q32: =IF(F32="MAT","No",IF(G32="","No",IF(M32="","No",IF(OR(NOT(ISNUMBER(O32)),O32<1,O32>4),"No","Sì")))) -> Sì | R32: =IF(F32="MAT","MAT - esclusa dal calcolo matrice",IF(G32="","Cod. 1 assente",IF(M32="","Peso PMI assente/non numerico",IF(NOT(ISNUMBER(O32)),"Risposta assente/non numerica",IF(OR(O32<1,O32>4),"Risposta fuori scala","Inclusa"))))) -> Inclusa | S32: =IF(Q32="Sì",O32*M32*J32,0) -> 5 | T32: =IF(Q32="Sì",M32*J32,0) -> 2.5 | U32: =IF(Q32="Sì",O32*M32*L32,0) -> 0 | V32: =IF(Q32="Sì",M32*L32,0) -> 0
A33: 30 | B33: 29 | C33: MQ1 | D33: MERCATO | E33: BRAND, COMUNICAZIONE E RAPPRESENTAZIONE | F33: M | G33: M | I33: =IF(G33="","",IFERROR(VLOOKUP(G33,'Note e assunzioni'!$A$23:$B$32,2,FALSE),"Codice non mappato")) -> Monitoring | J33: =IF(Q33="Sì",IF(H33="",1,0.7),0) -> 1 | K33: =IF(H33="","",IFERROR(VLOOKUP(H33,'Note e assunzioni'!$A$23:$B$32,2,FALSE),"Codice non mappato")) | L33: =IF(Q33="Sì",IF(H33="",0,0.3),0) -> 0 | M33: 3 | N33: 1.5 | O33: =IFERROR(INDEX('Input survey A'!$C$12:$C$67,MATCH(C33,'Input survey A'!$A$12:$A$67,0)),"") -> 2 | Q33: =IF(F33="MAT","No",IF(G33="","No",IF(M33="","No",IF(OR(NOT(ISNUMBER(O33)),O33<1,O33>4),"No","Sì")))) -> Sì | R33: =IF(F33="MAT","MAT - esclusa dal calcolo matrice",IF(G33="","Cod. 1 assente",IF(M33="","Peso PMI assente/non numerico",IF(NOT(ISNUMBER(O33)),"Risposta assente/non numerica",IF(OR(O33<1,O33>4),"Risposta fuori scala","Inclusa"))))) -> Inclusa | S33: =IF(Q33="Sì",O33*M33*J33,0) -> 6 | T33: =IF(Q33="Sì",M33*J33,0) -> 3 | U33: =IF(Q33="Sì",O33*M33*L33,0) -> 0 | V33: =IF(Q33="Sì",M33*L33,0) -> 0
A34: 31 | B34: 30 | C34: MQ2 | D34: MERCATO | E34: BRAND, COMUNICAZIONE E RAPPRESENTAZIONE | F34: EU | G34: EU | I34: =IF(G34="","",IFERROR(VLOOKUP(G34,'Note e assunzioni'!$A$23:$B$32,2,FALSE),"Codice non mappato")) -> End-users | J34: =IF(Q34="Sì",IF(H34="",1,0.7),0) -> 1 | K34: =IF(H34="","",IFERROR(VLOOKUP(H34,'Note e assunzioni'!$A$23:$B$32,2,FALSE),"Codice non mappato")) | L34: =IF(Q34="Sì",IF(H34="",0,0.3),0) -> 0 | M34: 3 | N34: 1 | O34: =IFERROR(INDEX('Input survey A'!$C$12:$C$67,MATCH(C34,'Input survey A'!$A$12:$A$67,0)),"") -> 4 | Q34: =IF(F34="MAT","No",IF(G34="","No",IF(M34="","No",IF(OR(NOT(ISNUMBER(O34)),O34<1,O34>4),"No","Sì")))) -> Sì | R34: =IF(F34="MAT","MAT - esclusa dal calcolo matrice",IF(G34="","Cod. 1 assente",IF(M34="","Peso PMI assente/non numerico",IF(NOT(ISNUMBER(O34)),"Risposta assente/non numerica",IF(OR(O34<1,O34>4),"Risposta fuori scala","Inclusa"))))) -> Inclusa | S34: =IF(Q34="Sì",O34*M34*J34,0) -> 12 | T34: =IF(Q34="Sì",M34*J34,0) -> 3 | U34: =IF(Q34="Sì",O34*M34*L34,0) -> 0 | V34: =IF(Q34="Sì",M34*L34,0) -> 0
A35: 32 | B35: 31 | C35: MQ3 | D35: MERCATO | E35: BRAND, COMUNICAZIONE E RAPPRESENTAZIONE | F35: EU/ND | G35: EU | H35: ND | I35: =IF(G35="","",IFERROR(VLOOKUP(G35,'Note e assunzioni'!$A$23:$B$32,2,FALSE),"Codice non mappato")) -> End-users | J35: =IF(Q35="Sì",IF(H35="",1,0.7),0) -> 0.7 | K35: =IF(H35="","",IFERROR(VLOOKUP(H35,'Note e assunzioni'!$A$23:$B$32,2,FALSE),"Codice non mappato")) -> Non-discrimination | L35: =IF(Q35="Sì",IF(H35="",0,0.3),0) -> 0.3 | M35: 3 | N35: 1.5 | O35: =IFERROR(INDEX('Input survey A'!$C$12:$C$67,MATCH(C35,'Input survey A'!$A$12:$A$67,0)),"") -> 2 | Q35: =IF(F35="MAT","No",IF(G35="","No",IF(M35="","No",IF(OR(NOT(ISNUMBER(O35)),O35<1,O35>4),"No","Sì")))) -> Sì | R35: =IF(F35="MAT","MAT - esclusa dal calcolo matrice",IF(G35="","Cod. 1 assente",IF(M35="","Peso PMI assente/non numerico",IF(NOT(ISNUMBER(O35)),"Risposta assente/non numerica",IF(OR(O35<1,O35>4),"Risposta fuori scala","Inclusa"))))) -> Inclusa | S35: =IF(Q35="Sì",O35*M35*J35,0) -> 4.2 | T35: =IF(Q35="Sì",M35*J35,0) -> 2.1 | U35: =IF(Q35="Sì",O35*M35*L35,0) -> 1.8 | V35: =IF(Q35="Sì",M35*L35,0) -> 0.9
A36: 33 | B36: 32 | C36: MQ4 | D36: MERCATO | E36: BRAND, COMUNICAZIONE E RAPPRESENTAZIONE | F36: EU | G36: EU | I36: =IF(G36="","",IFERROR(VLOOKUP(G36,'Note e assunzioni'!$A$23:$B$32,2,FALSE),"Codice non mappato")) -> End-users | J36: =IF(Q36="Sì",IF(H36="",1,0.7),0) -> 1 | K36: =IF(H36="","",IFERROR(VLOOKUP(H36,'Note e assunzioni'!$A$23:$B$32,2,FALSE),"Codice non mappato")) | L36: =IF(Q36="Sì",IF(H36="",0,0.3),0) -> 0 | M36: 3 | N36: 2.5 | O36: =IFERROR(INDEX('Input survey A'!$C$12:$C$67,MATCH(C36,'Input survey A'!$A$12:$A$67,0)),"") -> 2 | Q36: =IF(F36="MAT","No",IF(G36="","No",IF(M36="","No",IF(OR(NOT(ISNUMBER(O36)),O36<1,O36>4),"No","Sì")))) -> Sì | R36: =IF(F36="MAT","MAT - esclusa dal calcolo matrice",IF(G36="","Cod. 1 assente",IF(M36="","Peso PMI assente/non numerico",IF(NOT(ISNUMBER(O36)),"Risposta assente/non numerica",IF(OR(O36<1,O36>4),"Risposta fuori scala","Inclusa"))))) -> Inclusa | S36: =IF(Q36="Sì",O36*M36*J36,0) -> 6 | T36: =IF(Q36="Sì",M36*J36,0) -> 3 | U36: =IF(Q36="Sì",O36*M36*L36,0) -> 0 | V36: =IF(Q36="Sì",M36*L36,0) -> 0
A37: 34 | B37: 33 | C37: MQ5 | D37: MERCATO | E37: BRAND, COMUNICAZIONE E RAPPRESENTAZIONE | F37: M/EU | G37: M | H37: EU | I37: =IF(G37="","",IFERROR(VLOOKUP(G37,'Note e assunzioni'!$A$23:$B$32,2,FALSE),"Codice non mappato")) -> Monitoring | J37: =IF(Q37="Sì",IF(H37="",1,0.7),0) -> 0.7 | K37: =IF(H37="","",IFERROR(VLOOKUP(H37,'Note e assunzioni'!$A$23:$B$32,2,FALSE),"Codice non mappato")) -> End-users | L37: =IF(Q37="Sì",IF(H37="",0,0.3),0) -> 0.3 | M37: 3 | N37: 2 | O37: =IFERROR(INDEX('Input survey A'!$C$12:$C$67,MATCH(C37,'Input survey A'!$A$12:$A$67,0)),"") -> 1 | Q37: =IF(F37="MAT","No",IF(G37="","No",IF(M37="","No",IF(OR(NOT(ISNUMBER(O37)),O37<1,O37>4),"No","Sì")))) -> Sì | R37: =IF(F37="MAT","MAT - esclusa dal calcolo matrice",IF(G37="","Cod. 1 assente",IF(M37="","Peso PMI assente/non numerico",IF(NOT(ISNUMBER(O37)),"Risposta assente/non numerica",IF(OR(O37<1,O37>4),"Risposta fuori scala","Inclusa"))))) -> Inclusa | S37: =IF(Q37="Sì",O37*M37*J37,0) -> 2.1 | T37: =IF(Q37="Sì",M37*J37,0) -> 2.1 | U37: =IF(Q37="Sì",O37*M37*L37,0) -> 0.9 | V37: =IF(Q37="Sì",M37*L37,0) -> 0.9
A38: 35 | B38: 34 | C38: MQ6 | D38: MERCATO | E38: BRAND, COMUNICAZIONE E RAPPRESENTAZIONE | F38: M | G38: M | I38: =IF(G38="","",IFERROR(VLOOKUP(G38,'Note e assunzioni'!$A$23:$B$32,2,FALSE),"Codice non mappato")) -> Monitoring | J38: =IF(Q38="Sì",IF(H38="",1,0.7),0) -> 1 | K38: =IF(H38="","",IFERROR(VLOOKUP(H38,'Note e assunzioni'!$A$23:$B$32,2,FALSE),"Codice non mappato")) | L38: =IF(Q38="Sì",IF(H38="",0,0.3),0) -> 0 | M38: 3 | N38: 2 | O38: =IFERROR(INDEX('Input survey A'!$C$12:$C$67,MATCH(C38,'Input survey A'!$A$12:$A$67,0)),"") -> 1 | Q38: =IF(F38="MAT","No",IF(G38="","No",IF(M38="","No",IF(OR(NOT(ISNUMBER(O38)),O38<1,O38>4),"No","Sì")))) -> Sì | R38: =IF(F38="MAT","MAT - esclusa dal calcolo matrice",IF(G38="","Cod. 1 assente",IF(M38="","Peso PMI assente/non numerico",IF(NOT(ISNUMBER(O38)),"Risposta assente/non numerica",IF(OR(O38<1,O38>4),"Risposta fuori scala","Inclusa"))))) -> Inclusa | S38: =IF(Q38="Sì",O38*M38*J38,0) -> 3 | T38: =IF(Q38="Sì",M38*J38,0) -> 3 | U38: =IF(Q38="Sì",O38*M38*L38,0) -> 0 | V38: =IF(Q38="Sì",M38*L38,0) -> 0
A39: 36 | B39: 35 | C39: MQ7 | D39: MERCATO | E39: CLIENTI, UTENTI E ACCESSIBILITÀ | F39: EU | G39: EU | I39: =IF(G39="","",IFERROR(VLOOKUP(G39,'Note e assunzioni'!$A$23:$B$32,2,FALSE),"Codice non mappato")) -> End-users | J39: =IF(Q39="Sì",IF(H39="",1,0.7),0) -> 1 | K39: =IF(H39="","",IFERROR(VLOOKUP(H39,'Note e assunzioni'!$A$23:$B$32,2,FALSE),"Codice non mappato")) | L39: =IF(Q39="Sì",IF(H39="",0,0.3),0) -> 0 | M39: 3 | N39: 1.5 | O39: =IFERROR(INDEX('Input survey A'!$C$12:$C$67,MATCH(C39,'Input survey A'!$A$12:$A$67,0)),"") -> 2 | Q39: =IF(F39="MAT","No",IF(G39="","No",IF(M39="","No",IF(OR(NOT(ISNUMBER(O39)),O39<1,O39>4),"No","Sì")))) -> Sì | R39: =IF(F39="MAT","MAT - esclusa dal calcolo matrice",IF(G39="","Cod. 1 assente",IF(M39="","Peso PMI assente/non numerico",IF(NOT(ISNUMBER(O39)),"Risposta assente/non numerica",IF(OR(O39<1,O39>4),"Risposta fuori scala","Inclusa"))))) -> Inclusa | S39: =IF(Q39="Sì",O39*M39*J39,0) -> 6 | T39: =IF(Q39="Sì",M39*J39,0) -> 3 | U39: =IF(Q39="Sì",O39*M39*L39,0) -> 0 | V39: =IF(Q39="Sì",M39*L39,0) -> 0
A40: 37 | B40: 36 | C40: MQ8 | D40: MERCATO | E40: CLIENTI, UTENTI E ACCESSIBILITÀ | F40: M | G40: M | I40: =IF(G40="","",IFERROR(VLOOKUP(G40,'Note e assunzioni'!$A$23:$B$32,2,FALSE),"Codice non mappato")) -> Monitoring | J40: =IF(Q40="Sì",IF(H40="",1,0.7),0) -> 1 | K40: =IF(H40="","",IFERROR(VLOOKUP(H40,'Note e assunzioni'!$A$23:$B$32,2,FALSE),"Codice non mappato")) | L40: =IF(Q40="Sì",IF(H40="",0,0.3),0) -> 0 | M40: 3 | N40: 2 | O40: =IFERROR(INDEX('Input survey A'!$C$12:$C$67,MATCH(C40,'Input survey A'!$A$12:$A$67,0)),"") -> 2 | Q40: =IF(F40="MAT","No",IF(G40="","No",IF(M40="","No",IF(OR(NOT(ISNUMBER(O40)),O40<1,O40>4),"No","Sì")))) -> Sì | R40: =IF(F40="MAT","MAT - esclusa dal calcolo matrice",IF(G40="","Cod. 1 assente",IF(M40="","Peso PMI assente/non numerico",IF(NOT(ISNUMBER(O40)),"Risposta assente/non numerica",IF(OR(O40<1,O40>4),"Risposta fuori scala","Inclusa"))))) -> Inclusa | S40: =IF(Q40="Sì",O40*M40*J40,0) -> 6 | T40: =IF(Q40="Sì",M40*J40,0) -> 3 | U40: =IF(Q40="Sì",O40*M40*L40,0) -> 0 | V40: =IF(Q40="Sì",M40*L40,0) -> 0
A41: 38 | B41: 37 | C41: MQ9 | D41: MERCATO | E41: CLIENTI, UTENTI E ACCESSIBILITÀ | F41: EU/M | G41: EU | H41: M | I41: =IF(G41="","",IFERROR(VLOOKUP(G41,'Note e assunzioni'!$A$23:$B$32,2,FALSE),"Codice non mappato")) -> End-users | J41: =IF(Q41="Sì",IF(H41="",1,0.7),0) -> 0.7 | K41: =IF(H41="","",IFERROR(VLOOKUP(H41,'Note e assunzioni'!$A$23:$B$32,2,FALSE),"Codice non mappato")) -> Monitoring | L41: =IF(Q41="Sì",IF(H41="",0,0.3),0) -> 0.3 | M41: 3 | N41: 2.5 | O41: =IFERROR(INDEX('Input survey A'!$C$12:$C$67,MATCH(C41,'Input survey A'!$A$12:$A$67,0)),"") -> 1 | Q41: =IF(F41="MAT","No",IF(G41="","No",IF(M41="","No",IF(OR(NOT(ISNUMBER(O41)),O41<1,O41>4),"No","Sì")))) -> Sì | R41: =IF(F41="MAT","MAT - esclusa dal calcolo matrice",IF(G41="","Cod. 1 assente",IF(M41="","Peso PMI assente/non numerico",IF(NOT(ISNUMBER(O41)),"Risposta assente/non numerica",IF(OR(O41<1,O41>4),"Risposta fuori scala","Inclusa"))))) -> Inclusa | S41: =IF(Q41="Sì",O41*M41*J41,0) -> 2.1 | T41: =IF(Q41="Sì",M41*J41,0) -> 2.1 | U41: =IF(Q41="Sì",O41*M41*L41,0) -> 0.9 | V41: =IF(Q41="Sì",M41*L41,0) -> 0.9
...

Sheet Calcoli matrice C
A1: Calcoli matrice C
A2: Calcolo tema per tema della matrice: survey praticata vs reporting comunicata.
A3: Caso survey | B3: GM Spa
A4: Caso reporting | B4: 4BILD S.p.A.
A5: Soglia alta/bassa | B5: 2.5 | C5: non serve | D5: esempio
A6: Regola alta/bassa | B6: Alta > 2,50; Bassa <= 2,50
A8: Tema reporting | B8: Codice | C8: Score survey / praticata | D8: Livello survey | E8: Score reporting / comunicata | F8: Livello reporting | G8: Differenza reporting-survey | H8: Maturità survey | I8: Maturità reporting | J8: Quadrante matrice | K8: Interpretazione sintetica | L8: Priorità intervento | M8: Denominatore survey | N8: Check range
A9: Foundation | B9: F | C9: =IFERROR((SUMIF('Mappatura A-B-C'!$I$5:$I$59,A9,'Mappatura A-B-C'!$S$5:$S$59)+SUMIF('Mappatura A-B-C'!$K$5:$K$59,A9,'Mappatura A-B-C'!$U$5:$U$59))/(SUMIF('Mappatura A-B-C'!$I$5:$I$59,A9,'Mappatura A-B-C'!$T$5:$T$59)+SUMIF('Mappatura A-B-C'!$K$5:$K$59,A9,'Mappatura A-B-C'!$V$5:$V$59)),"") -> 1.8602151 | D9: =IF(C9="","",IF(C9<=1.5,"1 - Deriva - Discontinuo",IF(C9<=2.5,"2 - Rotta - Strutturato",IF(C9<=3.5,"3 - Orbita - Integrato","4 - Gravità - Sistemico / Consistente")))) -> 2 - Rotta - Strutturato | E9: =SUMIF('Input esterno GIorgia-per axY '!$F$9:$F$38,$B$4&"|"&A9,'Input esterno GIorgia-per axY '!$D$9:$D$38) -> 4 | F9: =IF(E9="","",IF(E9<=1.5,"1 - Deriva - Discontinuo",IF(E9<=2.5,"2 - Rotta - Strutturato",IF(E9<=3.5,"3 - Orbita - Integrato","4 - Gravità - Sistemico / Consistente")))) -> 4 - Gravità - Sistemico / Consistente | G9: =IF(OR(C9="",E9=""),"",E9-C9) -> 2.1397849 | H9: =IF(C9="","",IF(C9>$B$5,"Alta","Bassa")) -> Bassa | I9: =IF(E9="","",IF(E9>$B$5,"Alta","Bassa")) -> Alta | J9: =IF(AND(H9="Alta",I9="Alta"),"Allineamento virtuoso",IF(AND(H9="Alta",I9="Bassa"),"Potenziale nascosto",IF(AND(H9="Bassa",I9="Alta"),"Sovraesposizione","Area fragile"))) -> Sovraesposizione | K9: =IF(J9="Allineamento virtuoso","Area di coerenza: pratiche DEIA mature e disclosure strutturata risultano allineate.",IF(J9="Potenziale nascosto","Area di sottorendicontazione: pratiche più mature della disclosure esterna.",IF(J9="Sovraesposizione","Area di disallineamento comunicativo: la disclosure appare più avanzata della maturità praticata.","Area prioritaria di sviluppo: pratiche e disclosure risultano entrambe deboli."))) -> Area di disallineamento comunicativo: la disclosure appare più avanzata della maturità praticata. | L9: =IF(J9="Area fragile","Alta - rafforzare congiuntamente pratiche e disclosure",IF(J9="Sovraesposizione","Alta - validare evidenze interne e rafforzare pratiche/policy",IF(J9="Potenziale nascosto","Media-Alta - migliorare qualità, granularità e completezza della disclosure","Bassa - consolidare e usare come benchmark interno"))) -> Alta - validare evidenze interne e rafforzare pratiche/policy | M9: =(SUMIF('Mappatura A-B-C'!$I$5:$I$59,A9,'Mappatura A-B-C'!$T$5:$T$59)+SUMIF('Mappatura A-B-C'!$K$5:$K$59,A9,'Mappatura A-B-C'!$V$5:$V$59)) -> 13.95 | N9: =IF(AND(C9>=1,C9<=4,E9>=1,E9<=4),"OK","ERRORE") -> OK
A10: HR | B10: HR | C10: =IFERROR((SUMIF('Mappatura A-B-C'!$I$5:$I$59,A10,'Mappatura A-B-C'!$S$5:$S$59)+SUMIF('Mappatura A-B-C'!$K$5:$K$59,A10,'Mappatura A-B-C'!$U$5:$U$59))/(SUMIF('Mappatura A-B-C'!$I$5:$I$59,A10,'Mappatura A-B-C'!$T$5:$T$59)+SUMIF('Mappatura A-B-C'!$K$5:$K$59,A10,'Mappatura A-B-C'!$V$5:$V$59)),"") -> 2.5585106 | D10: =IF(C10="","",IF(C10<=1.5,"1 - Deriva - Discontinuo",IF(C10<=2.5,"2 - Rotta - Strutturato",IF(C10<=3.5,"3 - Orbita - Integrato","4 - Gravità - Sistemico / Consistente")))) -> 3 - Orbita - Integrato | E10: =SUMIF('Input esterno GIorgia-per axY '!$F$9:$F$38,$B$4&"|"&A10,'Input esterno GIorgia-per axY '!$D$9:$D$38) -> 3 | F10: =IF(E10="","",IF(E10<=1.5,"1 - Deriva - Discontinuo",IF(E10<=2.5,"2 - Rotta - Strutturato",IF(E10<=3.5,"3 - Orbita - Integrato","4 - Gravità - Sistemico / Consistente")))) -> 3 - Orbita - Integrato | G10: =IF(OR(C10="",E10=""),"",E10-C10) -> 0.44148936 | H10: =IF(C10="","",IF(C10>$B$5,"Alta","Bassa")) -> Alta | I10: =IF(E10="","",IF(E10>$B$5,"Alta","Bassa")) -> Alta | J10: =IF(AND(H10="Alta",I10="Alta"),"Allineamento virtuoso",IF(AND(H10="Alta",I10="Bassa"),"Potenziale nascosto",IF(AND(H10="Bassa",I10="Alta"),"Sovraesposizione","Area fragile"))) -> Allineamento virtuoso | K10: =IF(J10="Allineamento virtuoso","Area di coerenza: pratiche DEIA mature e disclosure strutturata risultano allineate.",IF(J10="Potenziale nascosto","Area di sottorendicontazione: pratiche più mature della disclosure esterna.",IF(J10="Sovraesposizione","Area di disallineamento comunicativo: la disclosure appare più avanzata della maturità praticata.","Area prioritaria di sviluppo: pratiche e disclosure risultano entrambe deboli."))) -> Area di coerenza: pratiche DEIA mature e disclosure strutturata risultano allineate. | L10: =IF(J10="Area fragile","Alta - rafforzare congiuntamente pratiche e disclosure",IF(J10="Sovraesposizione","Alta - validare evidenze interne e rafforzare pratiche/policy",IF(J10="Potenziale nascosto","Media-Alta - migliorare qualità, granularità e completezza della disclosure","Bassa - consolidare e usare come benchmark interno"))) -> Bassa - consolidare e usare come benchmark interno | M10: =(SUMIF('Mappatura A-B-C'!$I$5:$I$59,A10,'Mappatura A-B-C'!$T$5:$T$59)+SUMIF('Mappatura A-B-C'!$K$5:$K$59,A10,'Mappatura A-B-C'!$V$5:$V$59)) -> 9.4 | N10: =IF(AND(C10>=1,C10<=4,E10>=1,E10<=4),"OK","ERRORE") -> OK
A11: Employment | B11: E | C11: =IFERROR((SUMIF('Mappatura A-B-C'!$I$5:$I$59,A11,'Mappatura A-B-C'!$S$5:$S$59)+SUMIF('Mappatura A-B-C'!$K$5:$K$59,A11,'Mappatura A-B-C'!$U$5:$U$59))/(SUMIF('Mappatura A-B-C'!$I$5:$I$59,A11,'Mappatura A-B-C'!$T$5:$T$59)+SUMIF('Mappatura A-B-C'!$K$5:$K$59,A11,'Mappatura A-B-C'!$V$5:$V$59)),"") -> 2.0454545 | D11: =IF(C11="","",IF(C11<=1.5,"1 - Deriva - Discontinuo",IF(C11<=2.5,"2 - Rotta - Strutturato",IF(C11<=3.5,"3 - Orbita - Integrato","4 - Gravità - Sistemico / Consistente")))) -> 2 - Rotta - Strutturato | E11: =SUMIF('Input esterno GIorgia-per axY '!$F$9:$F$38,$B$4&"|"&A11,'Input esterno GIorgia-per axY '!$D$9:$D$38) -> 3 | F11: =IF(E11="","",IF(E11<=1.5,"1 - Deriva - Discontinuo",IF(E11<=2.5,"2 - Rotta - Strutturato",IF(E11<=3.5,"3 - Orbita - Integrato","4 - Gravità - Sistemico / Consistente")))) -> 3 - Orbita - Integrato | G11: =IF(OR(C11="",E11=""),"",E11-C11) -> 0.95454545 | H11: =IF(C11="","",IF(C11>$B$5,"Alta","Bassa")) -> Bassa | I11: =IF(E11="","",IF(E11>$B$5,"Alta","Bassa")) -> Alta | J11: =IF(AND(H11="Alta",I11="Alta"),"Allineamento virtuoso",IF(AND(H11="Alta",I11="Bassa"),"Potenziale nascosto",IF(AND(H11="Bassa",I11="Alta"),"Sovraesposizione","Area fragile"))) -> Sovraesposizione | K11: =IF(J11="Allineamento virtuoso","Area di coerenza: pratiche DEIA mature e disclosure strutturata risultano allineate.",IF(J11="Potenziale nascosto","Area di sottorendicontazione: pratiche più mature della disclosure esterna.",IF(J11="Sovraesposizione","Area di disallineamento comunicativo: la disclosure appare più avanzata della maturità praticata.","Area prioritaria di sviluppo: pratiche e disclosure risultano entrambe deboli."))) -> Area di disallineamento comunicativo: la disclosure appare più avanzata della maturità praticata. | L11: =IF(J11="Area fragile","Alta - rafforzare congiuntamente pratiche e disclosure",IF(J11="Sovraesposizione","Alta - validare evidenze interne e rafforzare pratiche/policy",IF(J11="Potenziale nascosto","Media-Alta - migliorare qualità, granularità e completezza della disclosure","Bassa - consolidare e usare come benchmark interno"))) -> Alta - validare evidenze interne e rafforzare pratiche/policy | M11: =(SUMIF('Mappatura A-B-C'!$I$5:$I$59,A11,'Mappatura A-B-C'!$T$5:$T$59)+SUMIF('Mappatura A-B-C'!$K$5:$K$59,A11,'Mappatura A-B-C'!$V$5:$V$59)) -> 18.7 | N11: =IF(AND(C11>=1,C11<=4,E11>=1,E11<=4),"OK","ERRORE") -> OK
