Workbook

Sheet Note e assunzioni
A1: Note e assunzioni
A2: Parametri e regole della matrice. La tabella codice->tema in A23:B32 e' richiamata dalle formule del foglio Mappatura A-B-C.
A3: Elemento | B3: Assunzione / nota
A4: Fonte asse X (praticata) | B4: qualtrix_output.xlsx, foglio Sheet0, riga 3
A5: Fonte asse Y (comunicata) | B5: elaborato_giorgia.xlsx, foglio matrice_y
A6: Fonte metodologia | B6: deia_core.py (mappatura, pesi, soglie)
A7: Caso survey | B7: 4BILD S.p.A. - Da 10 a 49 dipendenti
A8: Dimensione / peso usato | B8: PMI -> colonna Peso PMI
A9: Caso reporting | B9: 4BILD S.p.A.
A10: Regola MAT | B10: Le domande con Cod. standard = MAT sono escluse dalla matrice.
A11: Regola allocazione | B11: Cod. 1 = 100% se Cod. 2 e' vuoto; Cod. 1 = 70% e Cod. 2 = 30% se Cod. 2 e' valorizzato.
A12: Formula asse X | B12: Score = somma(risposta x peso x quota) / somma(peso x quota).
A13: Formula asse Y | B13: Valore intero 1-4 di content analysis per tema, non mediato (SUMIF su chiave Azienda|Tema).
A14: Soglia quadranti | B14: Bassa maturita' <= 2.50; alta maturita' > 2.50.
... A32: EU | B32: End-users

Sheet Input survey A
A1: Input survey A - risposte Qualtrics (asse X)
A3: File origine | B3: qualtrix_output.xlsx
A4: Foglio origine | B4: Sheet0
A5: Riga origine | B5: 3
A6: Ragione sociale | B6: 4BILD S.p.A.
A7: Tipo impresa | B7: PMI
A8: Peso usato | B8: Peso PMI
A11: Codice domanda | B11: Testo domanda | C11: Risposta survey | D11: Col. Qualtrics | E11: In mappatura
A12: CQ1 | B12: Le persone sono e si sentono libere di esprimere il proprio punto di vista e il proprio disaccordo? | C12: 3 | D12: P | E12: Sì
A13: CQ2 | B13: Esistono spazi e strumenti strutturati in cui le persone possano proporre miglioramenti? | C13: 1 | D13: Q | E13: Sì
A14: CQ3 | B14: Il linguaggio interno tiene in considerazione le diverse identità quali ad esempio il genere, i background culturali, il livello di istruzione? | C14: 3 | D14: R | E14: Sì
A15: CQ4 | B15: Esistono procedure e policy formalizzate per prevenire, contrastare e segnalare episodi di discriminazione, pregiudizio o microaggressioni? | C15: 2 | D15: S | E15: Sì
A16: CQ5 | B16: L’organizzazione prende in considerazione il tema della sicurezza psicologica? | C16: 4 | D16: T | E16: Sì
A17: PQ1 | B17: La comunicazione interna è accessibile? | C17: 2 | D17: U | E17: Sì
A18: PQ2 | B18: È presente un programma di inserimento (onboarding) per persone neo-assunte che promuove il valore dell'inclusione? | C18: 2 | D18: V | E18: Sì
A19: PQ3 | B19: Sono presenti misure di flessibilità e conciliazione vita-lavoro per supportare tutte le persone? | C19: 3 | D19: W | E19: Sì
A20: PQ4 | B20: L'organizzazione monitora l’accesso e l’utilizzo dei congedi parentali e familiari? | C20: 1 | D20: X | E20: Sì
A21: PQ5 | B21: L’organizzazione riflette e agisce sul rapporto tra longevità lavorativa, avanzamenti di carriera, sostenibilità dei ruoli e benessere delle persone nelle diverse fasi della vita professionale? | C21: 2 | D21: Y | E21: Sì
A22: PQ6 | B22: I processi HR considerano le specificità delle diverse identità, garantendo opportunità eque? | C22: 2 | D22: Z | E22: Sì
A23: PQ7 | B23: L'organizzazione prevede formazione per promuovere opportunità eque di carriera e lo sviluppo continuo delle competenze professionali? | C23: 1 | D23: AA | E23: Sì
... A67: SQ12 | B67: In che misura l'organizzazione assume decisioni finanziarie (es. budget, investimenti, incentivi) che tengono esplicitamente conto di obiettivi di diversità, equità, inclusione e accessibilità? | C67: 1 | D67: BS | E67: Sì

Sheet Input reporting B
A1: Input reporting B - content analysis (asse Y)
A3: File origine | B3: elaborato_giorgia.xlsx
A4: Foglio origine | B4: matrice_y
A8: Azienda | B8: Dimensione | C8: Tema reporting | D8: Score reporting | E8: Usato matrice | F8: Chiave lookup | G8: Riga fonte dataset
A9: 4BILD S.p.A. | B9: PMI | C9: Foundation | D9: 4 | E9: Sì | F9: 4BILD S.p.A.|Foundation | G9: 2
A10: 4BILD S.p.A. | B10: PMI | C10: HR | D10: 3 | E10: Sì | F10: 4BILD S.p.A.|HR | G10: 2
A11: 4BILD S.p.A. | B11: PMI | C11: Employment | D11: 3 | E11: Sì | F11: 4BILD S.p.A.|Employment | G11: 2
A12: 4BILD S.p.A. | B12: PMI | C12: Employees Engagement | D12: 3 | E12: Sì | F12: 4BILD S.p.A.|Employees Engagement | G12: 2
A13: 4BILD S.p.A. | B13: PMI | C13: Education & Training | D13: 3 | E13: Sì | F13: 4BILD S.p.A.|Education & Training | G13: 2
A14: 4BILD S.p.A. | B14: PMI | C14: Non-discrimination | D14: 4 | E14: Sì | F14: 4BILD S.p.A.|Non-discrimination | G14: 2
A15: 4BILD S.p.A. | B15: PMI | C15: Monitoring | D15: 3 | E15: Sì | F15: 4BILD S.p.A.|Monitoring | G15: 2
A16: 4BILD S.p.A. | B16: PMI | C16: Supply Chain Diversity | D16: 3 | E16: Sì | F16: 4BILD S.p.A.|Supply Chain Diversity | G16: 2
A17: 4BILD S.p.A. | B17: PMI | C17: Communities | D17: 3 | E17: Sì | F17: 4BILD S.p.A.|Communities | G17: 2
A18: 4BILD S.p.A. | B18: PMI | C18: End-users | D18: 2 | E18: Sì | F18: 4BILD S.p.A.|End-users | G18: 2

Sheet Mappatura A-B-C
A1: Mappatura A-B-C
A2: Mappatura domanda survey -> tema reporting con pesi, quote 70/30 e contributi al numeratore/denominatore dell'asse X.
A4: Col. Qualtrics | B4: N. | C4: Cod. domanda | D4: Framework diversity | E4: Sottogruppo | F4: Cod. standard | G4: Cod. 1 | H4: Cod. 2 | I4: Tema 1 | J4: % alloc. 1 | K4: Tema 2 | L4: % alloc. 2 | M4: Peso PMI | N4: Peso GRANDI | O4: Peso usato | P4: Risposta survey | Q4: Inclusa matrice | R4: Motivo esclusione / stato | S4: Contributo num. tema 1 | T4: Contributo den. tema 1 | U4: Contributo num. tema 2 | V4: Contributo den. tema 2
A5: P | B5: 1 | C5: CQ1 | D5: CULTURA | E5: CULTURA E COMPORTAMENTI | F5: MAT | I5: =IF(G5="","",IFERROR(VLOOKUP(G5,'Note e assunzioni'!$A$23:$B$32,2,FALSE),"Codice non mappato")) | J5: =IF(Q5="Sì",IF(H5="",1,0.7),0) | K5: =IF(H5="","",IFERROR(VLOOKUP(H5,'Note e assunzioni'!$A$23:$B$32,2,FALSE),"Codice non mappato")) | L5: =IF(Q5="Sì",IF(H5="",0,0.3),0) | M5: 1 | N5: 1 | O5: =IF('Input survey A'!$B$7="PMI",IF(M5="","",M5),IF(N5="","",N5)) | P5: =IFERROR(INDEX('Input survey A'!$C$12:$C$67,MATCH(C5,'Input survey A'!$A$12:$A$67,0)),"") | Q5: =IF(F5="MAT","No",IF(G5="","No",IF(O5="","No",IF(OR(NOT(ISNUMBER(P5)),P5<1,P5>4),"No","Sì")))) | R5: =IF(F5="MAT","MAT - esclusa dal calcolo matrice",IF(G5="","Cod. 1 assente",IF(O5="","Peso assente/non numerico",IF(NOT(ISNUMBER(P5)),"Risposta assente/non numerica",IF(OR(P5<1,P5>4),"Risposta fuori scala","Inclusa"))))) | S5: =IF(Q5="Sì",P5*O5*J5,0) | T5: =IF(Q5="Sì",O5*J5,0) | U5: =IF(Q5="Sì",P5*O5*L5,0) | V5: =IF(Q5="Sì",O5*L5,0)
A6: Q | B6: 2 | C6: CQ2 | D6: CULTURA | E6: CULTURA E COMPORTAMENTI | F6: EE | G6: EE | I6: =IF(G6="","",IFERROR(VLOOKUP(G6,'Note e assunzioni'!$A$23:$B$32,2,FALSE),"Codice non mappato")) | J6: =IF(Q6="Sì",IF(H6="",1,0.7),0) | K6: =IF(H6="","",IFERROR(VLOOKUP(H6,'Note e assunzioni'!$A$23:$B$32,2,FALSE),"Codice non mappato")) | L6: =IF(Q6="Sì",IF(H6="",0,0.3),0) | M6: 3 | N6: 2.5 | O6: =IF('Input survey A'!$B$7="PMI",IF(M6="","",M6),IF(N6="","",N6)) | P6: =IFERROR(INDEX('Input survey A'!$C$12:$C$67,MATCH(C6,'Input survey A'!$A$12:$A$67,0)),"") | Q6: =IF(F6="MAT","No",IF(G6="","No",IF(O6="","No",IF(OR(NOT(ISNUMBER(P6)),P6<1,P6>4),"No","Sì")))) | R6: =IF(F6="MAT","MAT - esclusa dal calcolo matrice",IF(G6="","Cod. 1 assente",IF(O6="","Peso assente/non numerico",IF(NOT(ISNUMBER(P6)),"Risposta assente/non numerica",IF(OR(P6<1,P6>4),"Risposta fuori scala","Inclusa"))))) | S6: =IF(Q6="Sì",P6*O6*J6,0) | T6: =IF(Q6="Sì",O6*J6,0) | U6: =IF(Q6="Sì",P6*O6*L6,0) | V6: =IF(Q6="Sì",O6*L6,0)
A7: R | B7: 3 | C7: CQ3 | D7: CULTURA | E7: CULTURA E COMPORTAMENTI | F7: EE/ND | G7: EE | H7: ND | I7: =IF(G7="","",IFERROR(VLOOKUP(G7,'Note e assunzioni'!$A$23:$B$32,2,FALSE),"Codice non mappato")) | J7: =IF(Q7="Sì",IF(H7="",1,0.7),0) | K7: =IF(H7="","",IFERROR(VLOOKUP(H7,'Note e assunzioni'!$A$23:$B$32,2,FALSE),"Codice non mappato")) | L7: =IF(Q7="Sì",IF(H7="",0,0.3),0) | M7: 3 | N7: 2 | O7: =IF('Input survey A'!$B$7="PMI",IF(M7="","",M7),IF(N7="","",N7)) | P7: =IFERROR(INDEX('Input survey A'!$C$12:$C$67,MATCH(C7,'Input survey A'!$A$12:$A$67,0)),"") | Q7: =IF(F7="MAT","No",IF(G7="","No",IF(O7="","No",IF(OR(NOT(ISNUMBER(P7)),P7<1,P7>4),"No","Sì")))) | R7: =IF(F7="MAT","MAT - esclusa dal calcolo matrice",IF(G7="","Cod. 1 assente",IF(O7="","Peso assente/non numerico",IF(NOT(ISNUMBER(P7)),"Risposta assente/non numerica",IF(OR(P7<1,P7>4),"Risposta fuori scala","Inclusa"))))) | S7: =IF(Q7="Sì",P7*O7*J7,0) | T7: =IF(Q7="Sì",O7*J7,0) | U7: =IF(Q7="Sì",P7*O7*L7,0) | V7: =IF(Q7="Sì",O7*L7,0)
A8: S | B8: 4 | C8: CQ4 | D8: CULTURA | E8: BENESSERE E SICUREZZA PSICOLOGICA | F8: ND | G8: ND | I8: =IF(G8="","",IFERROR(VLOOKUP(G8,'Note e assunzioni'!$A$23:$B$32,2,FALSE),"Codice non mappato")) | J8: =IF(Q8="Sì",IF(H8="",1,0.7),0) | K8: =IF(H8="","",IFERROR(VLOOKUP(H8,'Note e assunzioni'!$A$23:$B$32,2,FALSE),"Codice non mappato")) | L8: =IF(Q8="Sì",IF(H8="",0,0.3),0) | M8: 1 | N8: 1 | O8: =IF('Input survey A'!$B$7="PMI",IF(M8="","",M8),IF(N8="","",N8)) | P8: =IFERROR(INDEX('Input survey A'!$C$12:$C$67,MATCH(C8,'Input survey A'!$A$12:$A$67,0)),"") | Q8: =IF(F8="MAT","No",IF(G8="","No",IF(O8="","No",IF(OR(NOT(ISNUMBER(P8)),P8<1,P8>4),"No","Sì")))) | R8: =IF(F8="MAT","MAT - esclusa dal calcolo matrice",IF(G8="","Cod. 1 assente",IF(O8="","Peso assente/non numerico",IF(NOT(ISNUMBER(P8)),"Risposta assente/non numerica",IF(OR(P8<1,P8>4),"Risposta fuori scala","Inclusa"))))) | S8: =IF(Q8="Sì",P8*O8*J8,0) | T8: =IF(Q8="Sì",O8*J8,0) | U8: =IF(Q8="Sì",P8*O8*L8,0) | V8: =IF(Q8="Sì",O8*L8,0)
A9: T | B9: 5 | C9: CQ5 | D9: CULTURA | E9: BENESSERE E SICUREZZA PSICOLOGICA | F9: MAT | I9: =IF(G9="","",IFERROR(VLOOKUP(G9,'Note e assunzioni'!$A$23:$B$32,2,FALSE),"Codice non mappato")) | J9: =IF(Q9="Sì",IF(H9="",1,0.7),0) | K9: =IF(H9="","",IFERROR(VLOOKUP(H9,'Note e assunzioni'!$A$23:$B$32,2,FALSE),"Codice non mappato")) | L9: =IF(Q9="Sì",IF(H9="",0,0.3),0) | M9: 2.5 | N9: 1.5 | O9: =IF('Input survey A'!$B$7="PMI",IF(M9="","",M9),IF(N9="","",N9)) | P9: =IFERROR(INDEX('Input survey A'!$C$12:$C$67,MATCH(C9,'Input survey A'!$A$12:$A$67,0)),"") | Q9: =IF(F9="MAT","No",IF(G9="","No",IF(O9="","No",IF(OR(NOT(ISNUMBER(P9)),P9<1,P9>4),"No","Sì")))) | R9: =IF(F9="MAT","MAT - esclusa dal calcolo matrice",IF(G9="","Cod. 1 assente",IF(O9="","Peso assente/non numerico",IF(NOT(ISNUMBER(P9)),"Risposta assente/non numerica",IF(OR(P9<1,P9>4),"Risposta fuori scala","Inclusa"))))) | S9: =IF(Q9="Sì",P9*O9*J9,0) | T9: =IF(Q9="Sì",O9*J9,0) | U9: =IF(Q9="Sì",P9*O9*L9,0) | V9: =IF(Q9="Sì",O9*L9,0)
A10: U | B10: 6 | C10: PQ1 | D10: PROCESSI | E10: PROCESSI OPERATIVI E ACCESSIBILITÀ | F10: EE | G10: EE | I10: =IF(G10="","",IFERROR(VLOOKUP(G10,'Note e assunzioni'!$A$23:$B$32,2,FALSE),"Codice non mappato")) | J10: =IF(Q10="Sì",IF(H10="",1,0.7),0) | K10: =IF(H10="","",IFERROR(VLOOKUP(H10,'Note e assunzioni'!$A$23:$B$32,2,FALSE),"Codice non mappato")) | L10: =IF(Q10="Sì",IF(H10="",0,0.3),0) | M10: 1.5 | N10: 1 | O10: =IF('Input survey A'!$B$7="PMI",IF(M10="","",M10),IF(N10="","",N10)) | P10: =IFERROR(INDEX('Input survey A'!$C$12:$C$67,MATCH(C10,'Input survey A'!$A$12:$A$67,0)),"") | Q10: =IF(F10="MAT","No",IF(G10="","No",IF(O10="","No",IF(OR(NOT(ISNUMBER(P10)),P10<1,P10>4),"No","Sì")))) | R10: =IF(F10="MAT","MAT - esclusa dal calcolo matrice",IF(G10="","Cod. 1 assente",IF(O10="","Peso assente/non numerico",IF(NOT(ISNUMBER(P10)),"Risposta assente/non numerica",IF(OR(P10<1,P10>4),"Risposta fuori scala","Inclusa"))))) | S10: =IF(Q10="Sì",P10*O10*J10,0) | T10: =IF(Q10="Sì",O10*J10,0) | U10: =IF(Q10="Sì",P10*O10*L10,0) | V10: =IF(Q10="Sì",O10*L10,0)
A11: V | B11: 7 | C11: PQ2 | D11: PROCESSI | E11: PERSONE E PROCESSI | F11: ET1/ET2 | G11: ET | I11: =IF(G11="","",IFERROR(VLOOKUP(G11,'Note e assunzioni'!$A$23:$B$32,2,FALSE),"Codice non mappato")) | J11: =IF(Q11="Sì",IF(H11="",1,0.7),0) | K11: =IF(H11="","",IFERROR(VLOOKUP(H11,'Note e assunzioni'!$A$23:$B$32,2,FALSE),"Codice non mappato")) | L11: =IF(Q11="Sì",IF(H11="",0,0.3),0) | M11: 2.5 | N11: 1.5 | O11: =IF('Input survey A'!$B$7="PMI",IF(M11="","",M11),IF(N11="","",N11)) | P11: =IFERROR(INDEX('Input survey A'!$C$12:$C$67,MATCH(C11,'Input survey A'!$A$12:$A$67,0)),"") | Q11: =IF(F11="MAT","No",IF(G11="","No",IF(O11="","No",IF(OR(NOT(ISNUMBER(P11)),P11<1,P11>4),"No","Sì")))) | R11: =IF(F11="MAT","MAT - esclusa dal calcolo matrice",IF(G11="","Cod. 1 assente",IF(O11="","Peso assente/non numerico",IF(NOT(ISNUMBER(P11)),"Risposta assente/non numerica",IF(OR(P11<1,P11>4),"Risposta fuori scala","Inclusa"))))) | S11: =IF(Q11="Sì",P11*O11*J11,0) | T11: =IF(Q11="Sì",O11*J11,0) | U11: =IF(Q11="Sì",P11*O11*L11,0) | V11: =IF(Q11="Sì",O11*L11,0)
A12: W | B12: 8 | C12: PQ3 | D12: PROCESSI | E12: PERSONE E PROCESSI | F12: E2 | G12: E | I12: =IF(G12="","",IFERROR(VLOOKUP(G12,'Note e assunzioni'!$A$23:$B$32,2,FALSE),"Codice non mappato")) | J12: =IF(Q12="Sì",IF(H12="",1,0.7),0) | K12: =IF(H12="","",IFERROR(VLOOKUP(H12,'Note e assunzioni'!$A$23:$B$32,2,FALSE),"Codice non mappato")) | L12: =IF(Q12="Sì",IF(H12="",0,0.3),0) | M12: 1 | N12: 1 | O12: =IF('Input survey A'!$B$7="PMI",IF(M12="","",M12),IF(N12="","",N12)) | P12: =IFERROR(INDEX('Input survey A'!$C$12:$C$67,MATCH(C12,'Input survey A'!$A$12:$A$67,0)),"") | Q12: =IF(F12="MAT","No",IF(G12="","No",IF(O12="","No",IF(OR(NOT(ISNUMBER(P12)),P12<1,P12>4),"No","Sì")))) | R12: =IF(F12="MAT","MAT - esclusa dal calcolo matrice",IF(G12="","Cod. 1 assente",IF(O12="","Peso assente/non numerico",IF(NOT(ISNUMBER(P12)),"Risposta assente/non numerica",IF(OR(P12<1,P12>4),"Risposta fuori scala","Inclusa"))))) | S12: =IF(Q12="Sì",P12*O12*J12,0) | T12: =IF(Q12="Sì",O12*J12,0) | U12: =IF(Q12="Sì",P12*O12*L12,0) | V12: =IF(Q12="Sì",O12*L12,0)
A13: X | B13: 9 | C13: PQ4 | D13: PROCESSI | E13: PERSONE E PROCESSI | F13: E3 | G13: E | I13: =IF(G13="","",IFERROR(VLOOKUP(G13,'Note e assunzioni'!$A$23:$B$32,2,FALSE),"Codice non mappato")) | J13: =IF(Q13="Sì",IF(H13="",1,0.7),0) | K13: =IF(H13="","",IFERROR(VLOOKUP(H13,'Note e assunzioni'!$A$23:$B$32,2,FALSE),"Codice non mappato")) | L13: =IF(Q13="Sì",IF(H13="",0,0.3),0) | M13: 3 | N13: 2 | O13: =IF('Input survey A'!$B$7="PMI",IF(M13="","",M13),IF(N13="","",N13)) | P13: =IFERROR(INDEX('Input survey A'!$C$12:$C$67,MATCH(C13,'Input survey A'!$A$12:$A$67,0)),"") | Q13: =IF(F13="MAT","No",IF(G13="","No",IF(O13="","No",IF(OR(NOT(ISNUMBER(P13)),P13<1,P13>4),"No","Sì")))) | R13: =IF(F13="MAT","MAT - esclusa dal calcolo matrice",IF(G13="","Cod. 1 assente",IF(O13="","Peso assente/non numerico",IF(NOT(ISNUMBER(P13)),"Risposta assente/non numerica",IF(OR(P13<1,P13>4),"Risposta fuori scala","Inclusa"))))) | S13: =IF(Q13="Sì",P13*O13*J13,0) | T13: =IF(Q13="Sì",O13*J13,0) | U13: =IF(Q13="Sì",P13*O13*L13,0) | V13: =IF(Q13="Sì",O13*L13,0)
A14: Y | B14: 10 | C14: PQ5 | D14: PROCESSI | E14: PERSONE E PROCESSI | F14: E1/E2 | G14: E | I14: =IF(G14="","",IFERROR(VLOOKUP(G14,'Note e assunzioni'!$A$23:$B$32,2,FALSE),"Codice non mappato")) | J14: =IF(Q14="Sì",IF(H14="",1,0.7),0) | K14: =IF(H14="","",IFERROR(VLOOKUP(H14,'Note e assunzioni'!$A$23:$B$32,2,FALSE),"Codice non mappato")) | L14: =IF(Q14="Sì",IF(H14="",0,0.3),0) | M14: 3 | N14: 3 | O14: =IF('Input survey A'!$B$7="PMI",IF(M14="","",M14),IF(N14="","",N14)) | P14: =IFERROR(INDEX('Input survey A'!$C$12:$C$67,MATCH(C14,'Input survey A'!$A$12:$A$67,0)),"") | Q14: =IF(F14="MAT","No",IF(G14="","No",IF(O14="","No",IF(OR(NOT(ISNUMBER(P14)),P14<1,P14>4),"No","Sì")))) | R14: =IF(F14="MAT","MAT - esclusa dal calcolo matrice",IF(G14="","Cod. 1 assente",IF(O14="","Peso assente/non numerico",IF(NOT(ISNUMBER(P14)),"Risposta assente/non numerica",IF(OR(P14<1,P14>4),"Risposta fuori scala","Inclusa"))))) | S14: =IF(Q14="Sì",P14*O14*J14,0) | T14: =IF(Q14="Sì",O14*J14,0) | U14: =IF(Q14="Sì",P14*O14*L14,0) | V14: =IF(Q14="Sì",O14*L14,0)
A15: Z | B15: 11 | C15: PQ6 | D15: PROCESSI | E15: PERSONE E PROCESSI | F15: HR1/HR2 | G15: HR | I15: =IF(G15="","",IFERROR(VLOOKUP(G15,'Note e assunzioni'!$A$23:$B$32,2,FALSE),"Codice non mappato")) | J15: =IF(Q15="Sì",IF(H15="",1,0.7),0) | K15: =IF(H15="","",IFERROR(VLOOKUP(H15,'Note e assunzioni'!$A$23:$B$32,2,FALSE),"Codice non mappato")) | L15: =IF(Q15="Sì",IF(H15="",0,0.3),0) | M15: 2 | N15: 1 | O15: =IF('Input survey A'!$B$7="PMI",IF(M15="","",M15),IF(N15="","",N15)) | P15: =IFERROR(INDEX('Input survey A'!$C$12:$C$67,MATCH(C15,'Input survey A'!$A$12:$A$67,0)),"") | Q15: =IF(F15="MAT","No",IF(G15="","No",IF(O15="","No",IF(OR(NOT(ISNUMBER(P15)),P15<1,P15>4),"No","Sì")))) | R15: =IF(F15="MAT","MAT - esclusa dal calcolo matrice",IF(G15="","Cod. 1 assente",IF(O15="","Peso assente/non numerico",IF(NOT(ISNUMBER(P15)),"Risposta assente/non numerica",IF(OR(P15<1,P15>4),"Risposta fuori scala","Inclusa"))))) | S15: =IF(Q15="Sì",P15*O15*J15,0) | T15: =IF(Q15="Sì",O15*J15,0) | U15: =IF(Q15="Sì",P15*O15*L15,0) | V15: =IF(Q15="Sì",O15*L15,0)
A16: AA | B16: 12 | C16: PQ7 | D16: PROCESSI | E16: PERSONE E PROCESSI | F16: ET1/ET4 | G16: ET | I16: =IF(G16="","",IFERROR(VLOOKUP(G16,'Note e assunzioni'!$A$23:$B$32,2,FALSE),"Codice non mappato")) | J16: =IF(Q16="Sì",IF(H16="",1,0.7),0) | K16: =IF(H16="","",IFERROR(VLOOKUP(H16,'Note e assunzioni'!$A$23:$B$32,2,FALSE),"Codice non mappato")) | L16: =IF(Q16="Sì",IF(H16="",0,0.3),0) | M16: 2 | N16: 1.5 | O16: =IF('Input survey A'!$B$7="PMI",IF(M16="","",M16),IF(N16="","",N16)) | P16: =IFERROR(INDEX('Input survey A'!$C$12:$C$67,MATCH(C16,'Input survey A'!$A$12:$A$67,0)),"") | Q16: =IF(F16="MAT","No",IF(G16="","No",IF(O16="","No",IF(OR(NOT(ISNUMBER(P16)),P16<1,P16>4),"No","Sì")))) | R16: =IF(F16="MAT","MAT - esclusa dal calcolo matrice",IF(G16="","Cod. 1 assente",IF(O16="","Peso assente/non numerico",IF(NOT(ISNUMBER(P16)),"Risposta assente/non numerica",IF(OR(P16<1,P16>4),"Risposta fuori scala","Inclusa"))))) | S16: =IF(Q16="Sì",P16*O16*J16,0) | T16: =IF(Q16="Sì",O16*J16,0) | U16: =IF(Q16="Sì",P16*O16*L16,0) | V16: =IF(Q16="Sì",O16*L16,0)
A17: AB | B17: 13 | C17: CQ6 | D17: CULTURA | E17: FORMAZIONE E CONSAPEVOLEZZA | F17: ET2/ET3 | G17: ET | I17: =IF(G17="","",IFERROR(VLOOKUP(G17,'Note e assunzioni'!$A$23:$B$32,2,FALSE),"Codice non mappato")) | J17: =IF(Q17="Sì",IF(H17="",1,0.7),0) | K17: =IF(H17="","",IFERROR(VLOOKUP(H17,'Note e assunzioni'!$A$23:$B$32,2,FALSE),"Codice non mappato")) | L17: =IF(Q17="Sì",IF(H17="",0,0.3),0) | M17: 3 | N17: 1.5 | O17: =IF('Input survey A'!$B$7="PMI",IF(M17="","",M17),IF(N17="","",N17)) | P17: =IFERROR(INDEX('Input survey A'!$C$12:$C$67,MATCH(C17,'Input survey A'!$A$12:$A$67,0)),"") | Q17: =IF(F17="MAT","No",IF(G17="","No",IF(O17="","No",IF(OR(NOT(ISNUMBER(P17)),P17<1,P17>4),"No","Sì")))) | R17: =IF(F17="MAT","MAT - esclusa dal calcolo matrice",IF(G17="","Cod. 1 assente",IF(O17="","Peso assente/non numerico",IF(NOT(ISNUMBER(P17)),"Risposta assente/non numerica",IF(OR(P17<1,P17>4),"Risposta fuori scala","Inclusa"))))) | S17: =IF(Q17="Sì",P17*O17*J17,0) | T17: =IF(Q17="Sì",O17*J17,0) | U17: =IF(Q17="Sì",P17*O17*L17,0) | V17: =IF(Q17="Sì",O17*L17,0)
A18: AC | B18: 14 | C18: PQ8 | D18: PROCESSI | E18: PERSONE E PROCESSI | F18: HR2/E1 | G18: HR | H18: E | I18: =IF(G18="","",IFERROR(VLOOKUP(G18,'Note e assunzioni'!$A$23:$B$32,2,FALSE),"Codice non mappato")) | J18: =IF(Q18="Sì",IF(H18="",1,0.7),0) | K18: =IF(H18="","",IFERROR(VLOOKUP(H18,'Note e assunzioni'!$A$23:$B$32,2,FALSE),"Codice non mappato")) | L18: =IF(Q18="Sì",IF(H18="",0,0.3),0) | M18: 2.5 | N18: 1.5 | O18: =IF('Input survey A'!$B$7="PMI",IF(M18="","",M18),IF(N18="","",N18)) | P18: =IFERROR(INDEX('Input survey A'!$C$12:$C$67,MATCH(C18,'Input survey A'!$A$12:$A$67,0)),"") | Q18: =IF(F18="MAT","No",IF(G18="","No",IF(O18="","No",IF(OR(NOT(ISNUMBER(P18)),P18<1,P18>4),"No","Sì")))) | R18: =IF(F18="MAT","MAT - esclusa dal calcolo matrice",IF(G18="","Cod. 1 assente",IF(O18="","Peso assente/non numerico",IF(NOT(ISNUMBER(P18)),"Risposta assente/non numerica",IF(OR(P18<1,P18>4),"Risposta fuori scala","Inclusa"))))) | S18: =IF(Q18="Sì",P18*O18*J18,0) | T18: =IF(Q18="Sì",O18*J18,0) | U18: =IF(Q18="Sì",P18*O18*L18,0) | V18: =IF(Q18="Sì",O18*L18,0)
A19: AD | B19: 15 | C19: PQ9 | D19: PROCESSI | E19: PERSONE E PROCESSI | F19: HR2/E1 | G19: HR | H19: E | I19: =IF(G19="","",IFERROR(VLOOKUP(G19,'Note e assunzioni'!$A$23:$B$32,2,FALSE),"Codice non mappato")) | J19: =IF(Q19="Sì",IF(H19="",1,0.7),0) | K19: =IF(H19="","",IFERROR(VLOOKUP(H19,'Note e assunzioni'!$A$23:$B$32,2,FALSE),"Codice non mappato")) | L19: =IF(Q19="Sì",IF(H19="",0,0.3),0) | M19: 2.5 | N19: 1.5 | O19: =IF('Input survey A'!$B$7="PMI",IF(M19="","",M19),IF(N19="","",N19)) | P19: =IFERROR(INDEX('Input survey A'!$C$12:$C$67,MATCH(C19,'Input survey A'!$A$12:$A$67,0)),"") | Q19: =IF(F19="MAT","No",IF(G19="","No",IF(O19="","No",IF(OR(NOT(ISNUMBER(P19)),P19<1,P19>4),"No","Sì")))) | R19: =IF(F19="MAT","MAT - esclusa dal calcolo matrice",IF(G19="","Cod. 1 assente",IF(O19="","Peso assente/non numerico",IF(NOT(ISNUMBER(P19)),"Risposta assente/non numerica",IF(OR(P19<1,P19>4),"Risposta fuori scala","Inclusa"))))) | S19: =IF(Q19="Sì",P19*O19*J19,0) | T19: =IF(Q19="Sì",O19*J19,0) | U19: =IF(Q19="Sì",P19*O19*L19,0) | V19: =IF(Q19="Sì",O19*L19,0)
A20: AE | B20: 16 | C20: PQ10 | D20: PROCESSI | E20: PERSONE E PROCESSI | F20: M/HR1 | G20: M | H20: HR | I20: =IF(G20="","",IFERROR(VLOOKUP(G20,'Note e assunzioni'!$A$23:$B$32,2,FALSE),"Codice non mappato")) | J20: =IF(Q20="Sì",IF(H20="",1,0.7),0) | K20: =IF(H20="","",IFERROR(VLOOKUP(H20,'Note e assunzioni'!$A$23:$B$32,2,FALSE),"Codice non mappato")) | L20: =IF(Q20="Sì",IF(H20="",0,0.3),0) | M20: 3 | N20: 1.5 | O20: =IF('Input survey A'!$B$7="PMI",IF(M20="","",M20),IF(N20="","",N20)) | P20: =IFERROR(INDEX('Input survey A'!$C$12:$C$67,MATCH(C20,'Input survey A'!$A$12:$A$67,0)),"") | Q20: =IF(F20="MAT","No",IF(G20="","No",IF(O20="","No",IF(OR(NOT(ISNUMBER(P20)),P20<1,P20>4),"No","Sì")))) | R20: =IF(F20="MAT","MAT - esclusa dal calcolo matrice",IF(G20="","Cod. 1 assente",IF(O20="","Peso assente/non numerico",IF(NOT(ISNUMBER(P20)),"Risposta assente/non numerica",IF(OR(P20<1,P20>4),"Risposta fuori scala","Inclusa"))))) | S20: =IF(Q20="Sì",P20*O20*J20,0) | T20: =IF(Q20="Sì",O20*J20,0) | U20: =IF(Q20="Sì",P20*O20*L20,0) | V20: =IF(Q20="Sì",O20*L20,0)
A21: AF | B21: 17 | C21: PQ11 | D21: PROCESSI | E21: PERSONE E PROCESSI | F21: E2/E4 | G21: E | I21: =IF(G21="","",IFERROR(VLOOKUP(G21,'Note e assunzioni'!$A$23:$B$32,2,FALSE),"Codice non mappato")) | J21: =IF(Q21="Sì",IF(H21="",1,0.7),0) | K21: =IF(H21="","",IFERROR(VLOOKUP(H21,'Note e assunzioni'!$A$23:$B$32,2,FALSE),"Codice non mappato")) | L21: =IF(Q21="Sì",IF(H21="",0,0.3),0) | M21: 1.5 | N21: 1 | O21: =IF('Input survey A'!$B$7="PMI",IF(M21="","",M21),IF(N21="","",N21)) | P21: =IFERROR(INDEX('Input survey A'!$C$12:$C$67,MATCH(C21,'Input survey A'!$A$12:$A$67,0)),"") | Q21: =IF(F21="MAT","No",IF(G21="","No",IF(O21="","No",IF(OR(NOT(ISNUMBER(P21)),P21<1,P21>4),"No","Sì")))) | R21: =IF(F21="MAT","MAT - esclusa dal calcolo matrice",IF(G21="","Cod. 1 assente",IF(O21="","Peso assente/non numerico",IF(NOT(ISNUMBER(P21)),"Risposta assente/non numerica",IF(OR(P21<1,P21>4),"Risposta fuori scala","Inclusa"))))) | S21: =IF(Q21="Sì",P21*O21*J21,0) | T21: =IF(Q21="Sì",O21*J21,0) | U21: =IF(Q21="Sì",P21*O21*L21,0) | V21: =IF(Q21="Sì",O21*L21,0)
A22: AG | B22: 18 | C22: PQ12 | D22: PROCESSI | E22: PROCESSI OPERATIVI E ACCESSIBILITÀ | F22: E1/ND | G22: E | H22: ND | I22: =IF(G22="","",IFERROR(VLOOKUP(G22,'Note e assunzioni'!$A$23:$B$32,2,FALSE),"Codice non mappato")) | J22: =IF(Q22="Sì",IF(H22="",1,0.7),0) | K22: =IF(H22="","",IFERROR(VLOOKUP(H22,'Note e assunzioni'!$A$23:$B$32,2,FALSE),"Codice non mappato")) | L22: =IF(Q22="Sì",IF(H22="",0,0.3),0) | M22: 3 | N22: 2 | O22: =IF('Input survey A'!$B$7="PMI",IF(M22="","",M22),IF(N22="","",N22)) | P22: =IFERROR(INDEX('Input survey A'!$C$12:$C$67,MATCH(C22,'Input survey A'!$A$12:$A$67,0)),"") | Q22: =IF(F22="MAT","No",IF(G22="","No",IF(O22="","No",IF(OR(NOT(ISNUMBER(P22)),P22<1,P22>4),"No","Sì")))) | R22: =IF(F22="MAT","MAT - esclusa dal calcolo matrice",IF(G22="","Cod. 1 assente",IF(O22="","Peso assente/non numerico",IF(NOT(ISNUMBER(P22)),"Risposta assente/non numerica",IF(OR(P22<1,P22>4),"Risposta fuori scala","Inclusa"))))) | S22: =IF(Q22="Sì",P22*O22*J22,0) | T22: =IF(Q22="Sì",O22*J22,0) | U22: =IF(Q22="Sì",P22*O22*L22,0) | V22: =IF(Q22="Sì",O22*L22,0)
A23: AH | B23: 19 | C23: SQ1 | D23: STRATEGIA | E23: STRATEGIA E PIANIFICAZIONE | F23: F | G23: F | I23: =IF(G23="","",IFERROR(VLOOKUP(G23,'Note e assunzioni'!$A$23:$B$32,2,FALSE),"Codice non mappato")) | J23: =IF(Q23="Sì",IF(H23="",1,0.7),0) | K23: =IF(H23="","",IFERROR(VLOOKUP(H23,'Note e assunzioni'!$A$23:$B$32,2,FALSE),"Codice non mappato")) | L23: =IF(Q23="Sì",IF(H23="",0,0.3),0) | M23: 1.5 | N23: 1 | O23: =IF('Input survey A'!$B$7="PMI",IF(M23="","",M23),IF(N23="","",N23)) | P23: =IFERROR(INDEX('Input survey A'!$C$12:$C$67,MATCH(C23,'Input survey A'!$A$12:$A$67,0)),"") | Q23: =IF(F23="MAT","No",IF(G23="","No",IF(O23="","No",IF(OR(NOT(ISNUMBER(P23)),P23<1,P23>4),"No","Sì")))) | R23: =IF(F23="MAT","MAT - esclusa dal calcolo matrice",IF(G23="","Cod. 1 assente",IF(O23="","Peso assente/non numerico",IF(NOT(ISNUMBER(P23)),"Risposta assente/non numerica",IF(OR(P23<1,P23>4),"Risposta fuori scala","Inclusa"))))) | S23: =IF(Q23="Sì",P23*O23*J23,0) | T23: =IF(Q23="Sì",O23*J23,0) | U23: =IF(Q23="Sì",P23*O23*L23,0) | V23: =IF(Q23="Sì",O23*L23,0)
A24: AI | B24: 20 | C24: PQ13 | D24: PROCESSI | E24: PROCESSI OPERATIVI E ACCESSIBILITÀ | F24: E1 | G24: E | I24: =IF(G24="","",IFERROR(VLOOKUP(G24,'Note e assunzioni'!$A$23:$B$32,2,FALSE),"Codice non mappato")) | J24: =IF(Q24="Sì",IF(H24="",1,0.7),0) | K24: =IF(H24="","",IFERROR(VLOOKUP(H24,'Note e assunzioni'!$A$23:$B$32,2,FALSE),"Codice non mappato")) | L24: =IF(Q24="Sì",IF(H24="",0,0.3),0) | M24: 1.5 | N24: 1 | O24: =IF('Input survey A'!$B$7="PMI",IF(M24="","",M24),IF(N24="","",N24)) | P24: =IFERROR(INDEX('Input survey A'!$C$12:$C$67,MATCH(C24,'Input survey A'!$A$12:$A$67,0)),"") | Q24: =IF(F24="MAT","No",IF(G24="","No",IF(O24="","No",IF(OR(NOT(ISNUMBER(P24)),P24<1,P24>4),"No","Sì")))) | R24: =IF(F24="MAT","MAT - esclusa dal calcolo matrice",IF(G24="","Cod. 1 assente",IF(O24="","Peso assente/non numerico",IF(NOT(ISNUMBER(P24)),"Risposta assente/non numerica",IF(OR(P24<1,P24>4),"Risposta fuori scala","Inclusa"))))) | S24: =IF(Q24="Sì",P24*O24*J24,0) | T24: =IF(Q24="Sì",O24*J24,0) | U24: =IF(Q24="Sì",P24*O24*L24,0) | V24: =IF(Q24="Sì",O24*L24,0)
A25: AJ | B25: 21 | C25: PQ14 | D25: PROCESSI | E25: PROCESSI OPERATIVI E ACCESSIBILITÀ | F25: E1 | G25: E | I25: =IF(G25="","",IFERROR(VLOOKUP(G25,'Note e assunzioni'!$A$23:$B$32,2,FALSE),"Codice non mappato")) | J25: =IF(Q25="Sì",IF(H25="",1,0.7),0) | K25: =IF(H25="","",IFERROR(VLOOKUP(H25,'Note e assunzioni'!$A$23:$B$32,2,FALSE),"Codice non mappato")) | L25: =IF(Q25="Sì",IF(H25="",0,0.3),0) | M25: 1.5 | N25: 1 | O25: =IF('Input survey A'!$B$7="PMI",IF(M25="","",M25),IF(N25="","",N25)) | P25: =IFERROR(INDEX('Input survey A'!$C$12:$C$67,MATCH(C25,'Input survey A'!$A$12:$A$67,0)),"") | Q25: =IF(F25="MAT","No",IF(G25="","No",IF(O25="","No",IF(OR(NOT(ISNUMBER(P25)),P25<1,P25>4),"No","Sì")))) | R25: =IF(F25="MAT","MAT - esclusa dal calcolo matrice",IF(G25="","Cod. 1 assente",IF(O25="","Peso assente/non numerico",IF(NOT(ISNUMBER(P25)),"Risposta assente/non numerica",IF(OR(P25<1,P25>4),"Risposta fuori scala","Inclusa"))))) | S25: =IF(Q25="Sì",P25*O25*J25,0) | T25: =IF(Q25="Sì",O25*J25,0) | U25: =IF(Q25="Sì",P25*O25*L25,0) | V25: =IF(Q25="Sì",O25*L25,0)
A26: AK | B26: 22 | C26: PQ15 | D26: PROCESSI | E26: PROCESSI OPERATIVI E ACCESSIBILITÀ | F26: E1 | G26: E | I26: =IF(G26="","",IFERROR(VLOOKUP(G26,'Note e assunzioni'!$A$23:$B$32,2,FALSE),"Codice non mappato")) | J26: =IF(Q26="Sì",IF(H26="",1,0.7),0) | K26: =IF(H26="","",IFERROR(VLOOKUP(H26,'Note e assunzioni'!$A$23:$B$32,2,FALSE),"Codice non mappato")) | L26: =IF(Q26="Sì",IF(H26="",0,0.3),0) | M26: 1.5 | N26: 1 | O26: =IF('Input survey A'!$B$7="PMI",IF(M26="","",M26),IF(N26="","",N26)) | P26: =IFERROR(INDEX('Input survey A'!$C$12:$C$67,MATCH(C26,'Input survey A'!$A$12:$A$67,0)),"") | Q26: =IF(F26="MAT","No",IF(G26="","No",IF(O26="","No",IF(OR(NOT(ISNUMBER(P26)),P26<1,P26>4),"No","Sì")))) | R26: =IF(F26="MAT","MAT - esclusa dal calcolo matrice",IF(G26="","Cod. 1 assente",IF(O26="","Peso assente/non numerico",IF(NOT(ISNUMBER(P26)),"Risposta assente/non numerica",IF(OR(P26<1,P26>4),"Risposta fuori scala","Inclusa"))))) | S26: =IF(Q26="Sì",P26*O26*J26,0) | T26: =IF(Q26="Sì",O26*J26,0) | U26: =IF(Q26="Sì",P26*O26*L26,0) | V26: =IF(Q26="Sì",O26*L26,0)
A27: AL | B27: 23 | C27: PQ16 | D27: PROCESSI | E27: PROCESSI OPERATIVI E ACCESSIBILITÀ | F27: ND | G27: ND | I27: =IF(G27="","",IFERROR(VLOOKUP(G27,'Note e assunzioni'!$A$23:$B$32,2,FALSE),"Codice non mappato")) | J27: =IF(Q27="Sì",IF(H27="",1,0.7),0) | K27: =IF(H27="","",IFERROR(VLOOKUP(H27,'Note e assunzioni'!$A$23:$B$32,2,FALSE),"Codice non mappato")) | L27: =IF(Q27="Sì",IF(H27="",0,0.3),0) | M27: 3 | N27: 2 | O27: =IF('Input survey A'!$B$7="PMI",IF(M27="","",M27),IF(N27="","",N27)) | P27: =IFERROR(INDEX('Input survey A'!$C$12:$C$67,MATCH(C27,'Input survey A'!$A$12:$A$67,0)),"") | Q27: =IF(F27="MAT","No",IF(G27="","No",IF(O27="","No",IF(OR(NOT(ISNUMBER(P27)),P27<1,P27>4),"No","Sì")))) | R27: =IF(F27="MAT","MAT - esclusa dal calcolo matrice",IF(G27="","Cod. 1 assente",IF(O27="","Peso assente/non numerico",IF(NOT(ISNUMBER(P27)),"Risposta assente/non numerica",IF(OR(P27<1,P27>4),"Risposta fuori scala","Inclusa"))))) | S27: =IF(Q27="Sì",P27*O27*J27,0) | T27: =IF(Q27="Sì",O27*J27,0) | U27: =IF(Q27="Sì",P27*O27*L27,0) | V27: =IF(Q27="Sì",O27*L27,0)
A28: AM | B28: 24 | C28: SQ2 | D28: STRATEGIA | E28: GOVERNANCE E LEADERSHIP | F28: F | G28: F | I28: =IF(G28="","",IFERROR(VLOOKUP(G28,'Note e assunzioni'!$A$23:$B$32,2,FALSE),"Codice non mappato")) | J28: =IF(Q28="Sì",IF(H28="",1,0.7),0) | K28: =IF(H28="","",IFERROR(VLOOKUP(H28,'Note e assunzioni'!$A$23:$B$32,2,FALSE),"Codice non mappato")) | L28: =IF(Q28="Sì",IF(H28="",0,0.3),0) | M28: 2 | N28: 1 | O28: =IF('Input survey A'!$B$7="PMI",IF(M28="","",M28),IF(N28="","",N28)) | P28: =IFERROR(INDEX('Input survey A'!$C$12:$C$67,MATCH(C28,'Input survey A'!$A$12:$A$67,0)),"") | Q28: =IF(F28="MAT","No",IF(G28="","No",IF(O28="","No",IF(OR(NOT(ISNUMBER(P28)),P28<1,P28>4),"No","Sì")))) | R28: =IF(F28="MAT","MAT - esclusa dal calcolo matrice",IF(G28="","Cod. 1 assente",IF(O28="","Peso assente/non numerico",IF(NOT(ISNUMBER(P28)),"Risposta assente/non numerica",IF(OR(P28<1,P28>4),"Risposta fuori scala","Inclusa"))))) | S28: =IF(Q28="Sì",P28*O28*J28,0) | T28: =IF(Q28="Sì",O28*J28,0) | U28: =IF(Q28="Sì",P28*O28*L28,0) | V28: =IF(Q28="Sì",O28*L28,0)
A29: AN | B29: 25 | C29: SQ3 | D29: STRATEGIA | E29: GOVERNANCE E LEADERSHIP | F29: ET2/F | G29: ET | H29: F | I29: =IF(G29="","",IFERROR(VLOOKUP(G29,'Note e assunzioni'!$A$23:$B$32,2,FALSE),"Codice non mappato")) | J29: =IF(Q29="Sì",IF(H29="",1,0.7),0) | K29: =IF(H29="","",IFERROR(VLOOKUP(H29,'Note e assunzioni'!$A$23:$B$32,2,FALSE),"Codice non mappato")) | L29: =IF(Q29="Sì",IF(H29="",0,0.3),0) | M29: 3 | N29: 1.5 | O29: =IF('Input survey A'!$B$7="PMI",IF(M29="","",M29),IF(N29="","",N29)) | P29: =IFERROR(INDEX('Input survey A'!$C$12:$C$67,MATCH(C29,'Input survey A'!$A$12:$A$67,0)),"") | Q29: =IF(F29="MAT","No",IF(G29="","No",IF(O29="","No",IF(OR(NOT(ISNUMBER(P29)),P29<1,P29>4),"No","Sì")))) | R29: =IF(F29="MAT","MAT - esclusa dal calcolo matrice",IF(G29="","Cod. 1 assente",IF(O29="","Peso assente/non numerico",IF(NOT(ISNUMBER(P29)),"Risposta assente/non numerica",IF(OR(P29<1,P29>4),"Risposta fuori scala","Inclusa"))))) | S29: =IF(Q29="Sì",P29*O29*J29,0) | T29: =IF(Q29="Sì",O29*J29,0) | U29: =IF(Q29="Sì",P29*O29*L29,0) | V29: =IF(Q29="Sì",O29*L29,0)
A30: AO | B30: 26 | C30: SQ4 | D30: STRATEGIA | E30: GOVERNANCE E LEADERSHIP | F30: MAT | I30: =IF(G30="","",IFERROR(VLOOKUP(G30,'Note e assunzioni'!$A$23:$B$32,2,FALSE),"Codice non mappato")) | J30: =IF(Q30="Sì",IF(H30="",1,0.7),0) | K30: =IF(H30="","",IFERROR(VLOOKUP(H30,'Note e assunzioni'!$A$23:$B$32,2,FALSE),"Codice non mappato")) | L30: =IF(Q30="Sì",IF(H30="",0,0.3),0) | M30: 1.5 | N30: 1 | O30: =IF('Input survey A'!$B$7="PMI",IF(M30="","",M30),IF(N30="","",N30)) | P30: =IFERROR(INDEX('Input survey A'!$C$12:$C$67,MATCH(C30,'Input survey A'!$A$12:$A$67,0)),"") | Q30: =IF(F30="MAT","No",IF(G30="","No",IF(O30="","No",IF(OR(NOT(ISNUMBER(P30)),P30<1,P30>4),"No","Sì")))) | R30: =IF(F30="MAT","MAT - esclusa dal calcolo matrice",IF(G30="","Cod. 1 assente",IF(O30="","Peso assente/non numerico",IF(NOT(ISNUMBER(P30)),"Risposta assente/non numerica",IF(OR(P30<1,P30>4),"Risposta fuori scala","Inclusa"))))) | S30: =IF(Q30="Sì",P30*O30*J30,0) | T30: =IF(Q30="Sì",O30*J30,0) | U30: =IF(Q30="Sì",P30*O30*L30,0) | V30: =IF(Q30="Sì",O30*L30,0)
A31: AP | B31: 27 | C31: SQ5 | D31: STRATEGIA | E31: GOVERNANCE E LEADERSHIP | F31: M/F | G31: M | H31: F | I31: =IF(G31="","",IFERROR(VLOOKUP(G31,'Note e assunzioni'!$A$23:$B$32,2,FALSE),"Codice non mappato")) | J31: =IF(Q31="Sì",IF(H31="",1,0.7),0) | K31: =IF(H31="","",IFERROR(VLOOKUP(H31,'Note e assunzioni'!$A$23:$B$32,2,FALSE),"Codice non mappato")) | L31: =IF(Q31="Sì",IF(H31="",0,0.3),0) | M31: 3 | N31: 1.5 | O31: =IF('Input survey A'!$B$7="PMI",IF(M31="","",M31),IF(N31="","",N31)) | P31: =IFERROR(INDEX('Input survey A'!$C$12:$C$67,MATCH(C31,'Input survey A'!$A$12:$A$67,0)),"") | Q31: =IF(F31="MAT","No",IF(G31="","No",IF(O31="","No",IF(OR(NOT(ISNUMBER(P31)),P31<1,P31>4),"No","Sì")))) | R31: =IF(F31="MAT","MAT - esclusa dal calcolo matrice",IF(G31="","Cod. 1 assente",IF(O31="","Peso assente/non numerico",IF(NOT(ISNUMBER(P31)),"Risposta assente/non numerica",IF(OR(P31<1,P31>4),"Risposta fuori scala","Inclusa"))))) | S31: =IF(Q31="Sì",P31*O31*J31,0) | T31: =IF(Q31="Sì",O31*J31,0) | U31: =IF(Q31="Sì",P31*O31*L31,0) | V31: =IF(Q31="Sì",O31*L31,0)
A32: AQ | B32: 28 | C32: SQ6 | D32: STRATEGIA | E32: GOVERNANCE E LEADERSHIP | F32: F | G32: F | I32: =IF(G32="","",IFERROR(VLOOKUP(G32,'Note e assunzioni'!$A$23:$B$32,2,FALSE),"Codice non mappato")) | J32: =IF(Q32="Sì",IF(H32="",1,0.7),0) | K32: =IF(H32="","",IFERROR(VLOOKUP(H32,'Note e assunzioni'!$A$23:$B$32,2,FALSE),"Codice non mappato")) | L32: =IF(Q32="Sì",IF(H32="",0,0.3),0) | M32: 2.5 | N32: 1.5 | O32: =IF('Input survey A'!$B$7="PMI",IF(M32="","",M32),IF(N32="","",N32)) | P32: =IFERROR(INDEX('Input survey A'!$C$12:$C$67,MATCH(C32,'Input survey A'!$A$12:$A$67,0)),"") | Q32: =IF(F32="MAT","No",IF(G32="","No",IF(O32="","No",IF(OR(NOT(ISNUMBER(P32)),P32<1,P32>4),"No","Sì")))) | R32: =IF(F32="MAT","MAT - esclusa dal calcolo matrice",IF(G32="","Cod. 1 assente",IF(O32="","Peso assente/non numerico",IF(NOT(ISNUMBER(P32)),"Risposta assente/non numerica",IF(OR(P32<1,P32>4),"Risposta fuori scala","Inclusa"))))) | S32: =IF(Q32="Sì",P32*O32*J32,0) | T32: =IF(Q32="Sì",O32*J32,0) | U32: =IF(Q32="Sì",P32*O32*L32,0) | V32: =IF(Q32="Sì",O32*L32,0)
A33: AR | B33: 29 | C33: MQ1 | D33: MERCATO | E33: BRAND, COMUNICAZIONE E RAPPRESENTAZIONE | F33: M | G33: M | I33: =IF(G33="","",IFERROR(VLOOKUP(G33,'Note e assunzioni'!$A$23:$B$32,2,FALSE),"Codice non mappato")) | J33: =IF(Q33="Sì",IF(H33="",1,0.7),0) | K33: =IF(H33="","",IFERROR(VLOOKUP(H33,'Note e assunzioni'!$A$23:$B$32,2,FALSE),"Codice non mappato")) | L33: =IF(Q33="Sì",IF(H33="",0,0.3),0) | M33: 3 | N33: 1.5 | O33: =IF('Input survey A'!$B$7="PMI",IF(M33="","",M33),IF(N33="","",N33)) | P33: =IFERROR(INDEX('Input survey A'!$C$12:$C$67,MATCH(C33,'Input survey A'!$A$12:$A$67,0)),"") | Q33: =IF(F33="MAT","No",IF(G33="","No",IF(O33="","No",IF(OR(NOT(ISNUMBER(P33)),P33<1,P33>4),"No","Sì")))) | R33: =IF(F33="MAT","MAT - esclusa dal calcolo matrice",IF(G33="","Cod. 1 assente",IF(O33="","Peso assente/non numerico",IF(NOT(ISNUMBER(P33)),"Risposta assente/non numerica",IF(OR(P33<1,P33>4),"Risposta fuori scala","Inclusa"))))) | S33: =IF(Q33="Sì",P33*O33*J33,0) | T33: =IF(Q33="Sì",O33*J33,0) | U33: =IF(Q33="Sì",P33*O33*L33,0) | V33: =IF(Q33="Sì",O33*L33,0)
A34: AS | B34: 30 | C34: MQ2 | D34: MERCATO | E34: BRAND, COMUNICAZIONE E RAPPRESENTAZIONE | F34: EU | G34: EU | I34: =IF(G34="","",IFERROR(VLOOKUP(G34,'Note e assunzioni'!$A$23:$B$32,2,FALSE),"Codice non mappato")) | J34: =IF(Q34="Sì",IF(H34="",1,0.7),0) | K34: =IF(H34="","",IFERROR(VLOOKUP(H34,'Note e assunzioni'!$A$23:$B$32,2,FALSE),"Codice non mappato")) | L34: =IF(Q34="Sì",IF(H34="",0,0.3),0) | M34: 3 | N34: 1 | O34: =IF('Input survey A'!$B$7="PMI",IF(M34="","",M34),IF(N34="","",N34)) | P34: =IFERROR(INDEX('Input survey A'!$C$12:$C$67,MATCH(C34,'Input survey A'!$A$12:$A$67,0)),"") | Q34: =IF(F34="MAT","No",IF(G34="","No",IF(O34="","No",IF(OR(NOT(ISNUMBER(P34)),P34<1,P34>4),"No","Sì")))) | R34: =IF(F34="MAT","MAT - esclusa dal calcolo matrice",IF(G34="","Cod. 1 assente",IF(O34="","Peso assente/non numerico",IF(NOT(ISNUMBER(P34)),"Risposta assente/non numerica",IF(OR(P34<1,P34>4),"Risposta fuori scala","Inclusa"))))) | S34: =IF(Q34="Sì",P34*O34*J34,0) | T34: =IF(Q34="Sì",O34*J34,0) | U34: =IF(Q34="Sì",P34*O34*L34,0) | V34: =IF(Q34="Sì",O34*L34,0)
A35: AT | B35: 31 | C35: MQ3 | D35: MERCATO | E35: BRAND, COMUNICAZIONE E RAPPRESENTAZIONE | F35: EU/ND | G35: EU | H35: ND | I35: =IF(G35="","",IFERROR(VLOOKUP(G35,'Note e assunzioni'!$A$23:$B$32,2,FALSE),"Codice non mappato")) | J35: =IF(Q35="Sì",IF(H35="",1,0.7),0) | K35: =IF(H35="","",IFERROR(VLOOKUP(H35,'Note e assunzioni'!$A$23:$B$32,2,FALSE),"Codice non mappato")) | L35: =IF(Q35="Sì",IF(H35="",0,0.3),0) | M35: 3 | N35: 1.5 | O35: =IF('Input survey A'!$B$7="PMI",IF(M35="","",M35),IF(N35="","",N35)) | P35: =IFERROR(INDEX('Input survey A'!$C$12:$C$67,MATCH(C35,'Input survey A'!$A$12:$A$67,0)),"") | Q35: =IF(F35="MAT","No",IF(G35="","No",IF(O35="","No",IF(OR(NOT(ISNUMBER(P35)),P35<1,P35>4),"No","Sì")))) | R35: =IF(F35="MAT","MAT - esclusa dal calcolo matrice",IF(G35="","Cod. 1 assente",IF(O35="","Peso assente/non numerico",IF(NOT(ISNUMBER(P35)),"Risposta assente/non numerica",IF(OR(P35<1,P35>4),"Risposta fuori scala","Inclusa"))))) | S35: =IF(Q35="Sì",P35*O35*J35,0) | T35: =IF(Q35="Sì",O35*J35,0) | U35: =IF(Q35="Sì",P35*O35*L35,0) | V35: =IF(Q35="Sì",O35*L35,0)
A36: AU | B36: 32 | C36: MQ4 | D36: MERCATO | E36: BRAND, COMUNICAZIONE E RAPPRESENTAZIONE | F36: EU | G36: EU | I36: =IF(G36="","",IFERROR(VLOOKUP(G36,'Note e assunzioni'!$A$23:$B$32,2,FALSE),"Codice non mappato")) | J36: =IF(Q36="Sì",IF(H36="",1,0.7),0) | K36: =IF(H36="","",IFERROR(VLOOKUP(H36,'Note e assunzioni'!$A$23:$B$32,2,FALSE),"Codice non mappato")) | L36: =IF(Q36="Sì",IF(H36="",0,0.3),0) | M36: 3 | N36: 2.5 | O36: =IF('Input survey A'!$B$7="PMI",IF(M36="","",M36),IF(N36="","",N36)) | P36: =IFERROR(INDEX('Input survey A'!$C$12:$C$67,MATCH(C36,'Input survey A'!$A$12:$A$67,0)),"") | Q36: =IF(F36="MAT","No",IF(G36="","No",IF(O36="","No",IF(OR(NOT(ISNUMBER(P36)),P36<1,P36>4),"No","Sì")))) | R36: =IF(F36="MAT","MAT - esclusa dal calcolo matrice",IF(G36="","Cod. 1 assente",IF(O36="","Peso assente/non numerico",IF(NOT(ISNUMBER(P36)),"Risposta assente/non numerica",IF(OR(P36<1,P36>4),"Risposta fuori scala","Inclusa"))))) | S36: =IF(Q36="Sì",P36*O36*J36,0) | T36: =IF(Q36="Sì",O36*J36,0) | U36: =IF(Q36="Sì",P36*O36*L36,0) | V36: =IF(Q36="Sì",O36*L36,0)
A37: AV | B37: 33 | C37: MQ5 | D37: MERCATO | E37: BRAND, COMUNICAZIONE E RAPPRESENTAZIONE | F37: M/EU | G37: M | H37: EU | I37: =IF(G37="","",IFERROR(VLOOKUP(G37,'Note e assunzioni'!$A$23:$B$32,2,FALSE),"Codice non mappato")) | J37: =IF(Q37="Sì",IF(H37="",1,0.7),0) | K37: =IF(H37="","",IFERROR(VLOOKUP(H37,'Note e assunzioni'!$A$23:$B$32,2,FALSE),"Codice non mappato")) | L37: =IF(Q37="Sì",IF(H37="",0,0.3),0) | M37: 3 | N37: 2 | O37: =IF('Input survey A'!$B$7="PMI",IF(M37="","",M37),IF(N37="","",N37)) | P37: =IFERROR(INDEX('Input survey A'!$C$12:$C$67,MATCH(C37,'Input survey A'!$A$12:$A$67,0)),"") | Q37: =IF(F37="MAT","No",IF(G37="","No",IF(O37="","No",IF(OR(NOT(ISNUMBER(P37)),P37<1,P37>4),"No","Sì")))) | R37: =IF(F37="MAT","MAT - esclusa dal calcolo matrice",IF(G37="","Cod. 1 assente",IF(O37="","Peso assente/non numerico",IF(NOT(ISNUMBER(P37)),"Risposta assente/non numerica",IF(OR(P37<1,P37>4),"Risposta fuori scala","Inclusa"))))) | S37: =IF(Q37="Sì",P37*O37*J37,0) | T37: =IF(Q37="Sì",O37*J37,0) | U37: =IF(Q37="Sì",P37*O37*L37,0) | V37: =IF(Q37="Sì",O37*L37,0)
A38: AW | B38: 34 | C38: MQ6 | D38: MERCATO | E38: BRAND, COMUNICAZIONE E RAPPRESENTAZIONE | F38: M | G38: M | I38: =IF(G38="","",IFERROR(VLOOKUP(G38,'Note e assunzioni'!$A$23:$B$32,2,FALSE),"Codice non mappato")) | J38: =IF(Q38="Sì",IF(H38="",1,0.7),0) | K38: =IF(H38="","",IFERROR(VLOOKUP(H38,'Note e assunzioni'!$A$23:$B$32,2,FALSE),"Codice non mappato")) | L38: =IF(Q38="Sì",IF(H38="",0,0.3),0) | M38: 3 | N38: 2 | O38: =IF('Input survey A'!$B$7="PMI",IF(M38="","",M38),IF(N38="","",N38)) | P38: =IFERROR(INDEX('Input survey A'!$C$12:$C$67,MATCH(C38,'Input survey A'!$A$12:$A$67,0)),"") | Q38: =IF(F38="MAT","No",IF(G38="","No",IF(O38="","No",IF(OR(NOT(ISNUMBER(P38)),P38<1,P38>4),"No","Sì")))) | R38: =IF(F38="MAT","MAT - esclusa dal calcolo matrice",IF(G38="","Cod. 1 assente",IF(O38="","Peso assente/non numerico",IF(NOT(ISNUMBER(P38)),"Risposta assente/non numerica",IF(OR(P38<1,P38>4),"Risposta fuori scala","Inclusa"))))) | S38: =IF(Q38="Sì",P38*O38*J38,0) | T38: =IF(Q38="Sì",O38*J38,0) | U38: =IF(Q38="Sì",P38*O38*L38,0) | V38: =IF(Q38="Sì",O38*L38,0)
A39: AX | B39: 35 | C39: MQ7 | D39: MERCATO | E39: CLIENTI, UTENTI E ACCESSIBILITÀ | F39: EU | G39: EU | I39: =IF(G39="","",IFERROR(VLOOKUP(G39,'Note e assunzioni'!$A$23:$B$32,2,FALSE),"Codice non mappato")) | J39: =IF(Q39="Sì",IF(H39="",1,0.7),0) | K39: =IF(H39="","",IFERROR(VLOOKUP(H39,'Note e assunzioni'!$A$23:$B$32,2,FALSE),"Codice non mappato")) | L39: =IF(Q39="Sì",IF(H39="",0,0.3),0) | M39: 3 | N39: 1.5 | O39: =IF('Input survey A'!$B$7="PMI",IF(M39="","",M39),IF(N39="","",N39)) | P39: =IFERROR(INDEX('Input survey A'!$C$12:$C$67,MATCH(C39,'Input survey A'!$A$12:$A$67,0)),"") | Q39: =IF(F39="MAT","No",IF(G39="","No",IF(O39="","No",IF(OR(NOT(ISNUMBER(P39)),P39<1,P39>4),"No","Sì")))) | R39: =IF(F39="MAT","MAT - esclusa dal calcolo matrice",IF(G39="","Cod. 1 assente",IF(O39="","Peso assente/non numerico",IF(NOT(ISNUMBER(P39)),"Risposta assente/non numerica",IF(OR(P39<1,P39>4),"Risposta fuori scala","Inclusa"))))) | S39: =IF(Q39="Sì",P39*O39*J39,0) | T39: =IF(Q39="Sì",O39*J39,0) | U39: =IF(Q39="Sì",P39*O39*L39,0) | V39: =IF(Q39="Sì",O39*L39,0)
A40: AY | B40: 36 | C40: MQ8 | D40: MERCATO | E40: CLIENTI, UTENTI E ACCESSIBILITÀ | F40: M | G40: M | I40: =IF(G40="","",IFERROR(VLOOKUP(G40,'Note e assunzioni'!$A$23:$B$32,2,FALSE),"Codice non mappato")) | J40: =IF(Q40="Sì",IF(H40="",1,0.7),0) | K40: =IF(H40="","",IFERROR(VLOOKUP(H40,'Note e assunzioni'!$A$23:$B$32,2,FALSE),"Codice non mappato")) | L40: =IF(Q40="Sì",IF(H40="",0,0.3),0) | M40: 3 | N40: 2 | O40: =IF('Input survey A'!$B$7="PMI",IF(M40="","",M40),IF(N40="","",N40)) | P40: =IFERROR(INDEX('Input survey A'!$C$12:$C$67,MATCH(C40,'Input survey A'!$A$12:$A$67,0)),"") | Q40: =IF(F40="MAT","No",IF(G40="","No",IF(O40="","No",IF(OR(NOT(ISNUMBER(P40)),P40<1,P40>4),"No","Sì")))) | R40: =IF(F40="MAT","MAT - esclusa dal calcolo matrice",IF(G40="","Cod. 1 assente",IF(O40="","Peso assente/non numerico",IF(NOT(ISNUMBER(P40)),"Risposta assente/non numerica",IF(OR(P40<1,P40>4),"Risposta fuori scala","Inclusa"))))) | S40: =IF(Q40="Sì",P40*O40*J40,0) | T40: =IF(Q40="Sì",O40*J40,0) | U40: =IF(Q40="Sì",P40*O40*L40,0) | V40: =IF(Q40="Sì",O40*L40,0)
A41: AZ | B41: 37 | C41: MQ9 | D41: MERCATO | E41: CLIENTI, UTENTI E ACCESSIBILITÀ | F41: EU/M | G41: EU | H41: M | I41: =IF(G41="","",IFERROR(VLOOKUP(G41,'Note e assunzioni'!$A$23:$B$32,2,FALSE),"Codice non mappato")) | J41: =IF(Q41="Sì",IF(H41="",1,0.7),0) | K41: =IF(H41="","",IFERROR(VLOOKUP(H41,'Note e assunzioni'!$A$23:$B$32,2,FALSE),"Codice non mappato")) | L41: =IF(Q41="Sì",IF(H41="",0,0.3),0) | M41: 3 | N41: 2.5 | O41: =IF('Input survey A'!$B$7="PMI",IF(M41="","",M41),IF(N41="","",N41)) | P41: =IFERROR(INDEX('Input survey A'!$C$12:$C$67,MATCH(C41,'Input survey A'!$A$12:$A$67,0)),"") | Q41: =IF(F41="MAT","No",IF(G41="","No",IF(O41="","No",IF(OR(NOT(ISNUMBER(P41)),P41<1,P41>4),"No","Sì")))) | R41: =IF(F41="MAT","MAT - esclusa dal calcolo matrice",IF(G41="","Cod. 1 assente",IF(O41="","Peso assente/non numerico",IF(NOT(ISNUMBER(P41)),"Risposta assente/non numerica",IF(OR(P41<1,P41>4),"Risposta fuori scala","Inclusa"))))) | S41: =IF(Q41="Sì",P41*O41*J41,0) | T41: =IF(Q41="Sì",O41*J41,0) | U41: =IF(Q41="Sì",P41*O41*L41,0) | V41: =IF(Q41="Sì",O41*L41,0)
...

Sheet Calcoli matrice C
A1: Calcoli matrice C
A2: Confronto tema per tema: asse X praticata (survey) vs asse Y comunicata (reporting).
A3: Caso survey (X) | B3: 4BILD S.p.A.
A4: Caso reporting (Y) | B4: 4BILD S.p.A.
A5: Soglia alta/bassa | B5: 2.5
A6: Regola alta/bassa | B6: Alta > 2.50; Bassa <= 2.50
A8: Tema reporting | B8: Codice | C8: Score survey X (praticata) | D8: Livello survey | E8: Score reporting Y (comunicata) | F8: Livello reporting | G8: Differenza Y-X | H8: Maturita' survey | I8: Maturita' reporting | J8: Quadrante matrice | K8: Interpretazione sintetica | L8: Priorita' intervento | M8: Denominatore survey | N8: Check range
A9: Foundation | B9: F | C9: =IFERROR((SUMIF('Mappatura A-B-C'!$I$5:$I$59,$A9,'Mappatura A-B-C'!$S$5:$S$59)+SUMIF('Mappatura A-B-C'!$K$5:$K$59,$A9,'Mappatura A-B-C'!$U$5:$U$59))/(SUMIF('Mappatura A-B-C'!$I$5:$I$59,$A9,'Mappatura A-B-C'!$T$5:$T$59)+SUMIF('Mappatura A-B-C'!$K$5:$K$59,$A9,'Mappatura A-B-C'!$V$5:$V$59)),"") | D9: =IF(C9="","",IF(C9<=1.5,"1 - Deriva - Discontinuo",IF(C9<=2.5,"2 - Rotta - Strutturato",IF(C9<=3.5,"3 - Orbita - Integrato","4 - Gravità - Sistemico / Consistente")))) | E9: =SUMIF('Input reporting B'!$F$9:$F$18,$B$4&"|"&$A9,'Input reporting B'!$D$9:$D$18) | F9: =IF(E9="","",IF(E9<=1.5,"1 - Deriva - Discontinuo",IF(E9<=2.5,"2 - Rotta - Strutturato",IF(E9<=3.5,"3 - Orbita - Integrato","4 - Gravità - Sistemico / Consistente")))) | G9: =IF(OR(C9="",E9=""),"",E9-C9) | H9: =IF(C9="","",IF(C9>$B$5,"Alta","Bassa")) | I9: =IF(E9="","",IF(E9>$B$5,"Alta","Bassa")) | J9: =IF(AND(H9="Alta",I9="Alta"),"Allineamento virtuoso",IF(AND(H9="Alta",I9="Bassa"),"Potenziale nascosto",IF(AND(H9="Bassa",I9="Alta"),"Sovraesposizione","Area fragile"))) | K9: =IF(J9="Allineamento virtuoso","Area di coerenza: pratiche DEIA mature e disclosure strutturata risultano allineate.",IF(J9="Potenziale nascosto","Area di sottorendicontazione: pratiche più mature della disclosure esterna.",IF(J9="Sovraesposizione","Area di disallineamento comunicativo: la disclosure appare più avanzata della maturità praticata.","Area prioritaria di sviluppo: pratiche e disclosure risultano entrambe deboli."))) | L9: =IF(J9="Area fragile","Alta - rafforzare congiuntamente pratiche e disclosure",IF(J9="Sovraesposizione","Alta - validare evidenze interne e rafforzare pratiche/policy",IF(J9="Potenziale nascosto","Media-Alta - migliorare qualità, granularità e completezza della disclosure","Bassa - consolidare e usare come benchmark interno"))) | M9: =(SUMIF('Mappatura A-B-C'!$I$5:$I$59,$A9,'Mappatura A-B-C'!$T$5:$T$59)+SUMIF('Mappatura A-B-C'!$K$5:$K$59,$A9,'Mappatura A-B-C'!$V$5:$V$59)) | N9: =IF(AND(C9>=1,C9<=4,E9>=1,E9<=4),"OK","ERRORE")
A10: HR | B10: HR | C10: =IFERROR((SUMIF('Mappatura A-B-C'!$I$5:$I$59,$A10,'Mappatura A-B-C'!$S$5:$S$59)+SUMIF('Mappatura A-B-C'!$K$5:$K$59,$A10,'Mappatura A-B-C'!$U$5:$U$59))/(SUMIF('Mappatura A-B-C'!$I$5:$I$59,$A10,'Mappatura A-B-C'!$T$5:$T$59)+SUMIF('Mappatura A-B-C'!$K$5:$K$59,$A10,'Mappatura A-B-C'!$V$5:$V$59)),"") | D10: =IF(C10="","",IF(C10<=1.5,"1 - Deriva - Discontinuo",IF(C10<=2.5,"2 - Rotta - Strutturato",IF(C10<=3.5,"3 - Orbita - Integrato","4 - Gravità - Sistemico / Consistente")))) | E10: =SUMIF('Input reporting B'!$F$9:$F$18,$B$4&"|"&$A10,'Input reporting B'!$D$9:$D$18) | F10: =IF(E10="","",IF(E10<=1.5,"1 - Deriva - Discontinuo",IF(E10<=2.5,"2 - Rotta - Strutturato",IF(E10<=3.5,"3 - Orbita - Integrato","4 - Gravità - Sistemico / Consistente")))) | G10: =IF(OR(C10="",E10=""),"",E10-C10) | H10: =IF(C10="","",IF(C10>$B$5,"Alta","Bassa")) | I10: =IF(E10="","",IF(E10>$B$5,"Alta","Bassa")) | J10: =IF(AND(H10="Alta",I10="Alta"),"Allineamento virtuoso",IF(AND(H10="Alta",I10="Bassa"),"Potenziale nascosto",IF(AND(H10="Bassa",I10="Alta"),"Sovraesposizione","Area fragile"))) | K10: =IF(J10="Allineamento virtuoso","Area di coerenza: pratiche DEIA mature e disclosure strutturata risultano allineate.",IF(J10="Potenziale nascosto","Area di sottorendicontazione: pratiche più mature della disclosure esterna.",IF(J10="Sovraesposizione","Area di disallineamento comunicativo: la disclosure appare più avanzata della maturità praticata.","Area prioritaria di sviluppo: pratiche e disclosure risultano entrambe deboli."))) | L10: =IF(J10="Area fragile","Alta - rafforzare congiuntamente pratiche e disclosure",IF(J10="Sovraesposizione","Alta - validare evidenze interne e rafforzare pratiche/policy",IF(J10="Potenziale nascosto","Media-Alta - migliorare qualità, granularità e completezza della disclosure","Bassa - consolidare e usare come benchmark interno"))) | M10: =(SUMIF('Mappatura A-B-C'!$I$5:$I$59,$A10,'Mappatura A-B-C'!$T$5:$T$59)+SUMIF('Mappatura A-B-C'!$K$5:$K$59,$A10,'Mappatura A-B-C'!$V$5:$V$59)) | N10: =IF(AND(C10>=1,C10<=4,E10>=1,E10<=4),"OK","ERRORE")
A11: Employment | B11: E | C11: =IFERROR((SUMIF('Mappatura A-B-C'!$I$5:$I$59,$A11,'Mappatura A-B-C'!$S$5:$S$59)+SUMIF('Mappatura A-B-C'!$K$5:$K$59,$A11,'Mappatura A-B-C'!$U$5:$U$59))/(SUMIF('Mappatura A-B-C'!$I$5:$I$59,$A11,'Mappatura A-B-C'!$T$5:$T$59)+SUMIF('Mappatura A-B-C'!$K$5:$K$59,$A11,'Mappatura A-B-C'!$V$5:$V$59)),"") | D11: =IF(C11="","",IF(C11<=1.5,"1 - Deriva - Discontinuo",IF(C11<=2.5,"2 - Rotta - Strutturato",IF(C11<=3.5,"3 - Orbita - Integrato","4 - Gravità - Sistemico / Consistente")))) | E11: =SUMIF('Input reporting B'!$F$9:$F$18,$B$4&"|"&$A11,'Input reporting B'!$D$9:$D$18) | F11: =IF(E11="","",IF(E11<=1.5,"1 - Deriva - Discontinuo",IF(E11<=2.5,"2 - Rotta - Strutturato",IF(E11<=3.5,"3 - Orbita - Integrato","4 - Gravità - Sistemico / Consistente")))) | G11: =IF(OR(C11="",E11=""),"",E11-C11) | H11: =IF(C11="","",IF(C11>$B$5,"Alta","Bassa")) | I11: =IF(E11="","",IF(E11>$B$5,"Alta","Bassa")) | J11: =IF(AND(H11="Alta",I11="Alta"),"Allineamento virtuoso",IF(AND(H11="Alta",I11="Bassa"),"Potenziale nascosto",IF(AND(H11="Bassa",I11="Alta"),"Sovraesposizione","Area fragile"))) | K11: =IF(J11="Allineamento virtuoso","Area di coerenza: pratiche DEIA mature e disclosure strutturata risultano allineate.",IF(J11="Potenziale nascosto","Area di sottorendicontazione: pratiche più mature della disclosure esterna.",IF(J11="Sovraesposizione","Area di disallineamento comunicativo: la disclosure appare più avanzata della maturità praticata.","Area prioritaria di sviluppo: pratiche e disclosure risultano entrambe deboli."))) | L11: =IF(J11="Area fragile","Alta - rafforzare congiuntamente pratiche e disclosure",IF(J11="Sovraesposizione","Alta - validare evidenze interne e rafforzare pratiche/policy",IF(J11="Potenziale nascosto","Media-Alta - migliorare qualità, granularità e completezza della disclosure","Bassa - consolidare e usare come benchmark interno"))) | M11: =(SUMIF('Mappatura A-B-C'!$I$5:$I$59,$A11,'Mappatura A-B-C'!$T$5:$T$59)+SUMIF('Mappatura A-B-C'!$K$5:$K$59,$A11,'Mappatura A-B-C'!$V$5:$V$59)) | N11: =IF(AND(C11>=1,C11<=4,E11>=1,E11<=4),"OK","ERRORE")
A12: Employees Engagement | B12: EE | C12: =IFERROR((SUMIF('Mappatura A-B-C'!$I$5:$I$59,$A12,'Mappatura A-B-C'!$S$5:$S$59)+SUMIF('Mappatura A-B-C'!$K$5:$K$59,$A12,'Mappatura A-B-C'!$U$5:$U$59))/(SUMIF('Mappatura A-B-C'!$I$5:$I$59,$A12,'Mappatura A-B-C'!$T$5:$T$59)+SUMIF('Mappatura A-B-C'!$K$5:$K$59,$A12,'Mappatura A-B-C'!$V$5:$V$59)),"") | D12: =IF(C12="","",IF(C12<=1.5,"1 - Deriva - Discontinuo",IF(C12<=2.5,"2 - Rotta - Strutturato",IF(C12<=3.5,"3 - Orbita - Integrato","4 - Gravità - Sistemico / Consistente")))) | E12: =SUMIF('Input reporting B'!$F$9:$F$18,$B$4&"|"&$A12,'Input reporting B'!$D$9:$D$18) | F12: =IF(E12="","",IF(E12<=1.5,"1 - Deriva - Discontinuo",IF(E12<=2.5,"2 - Rotta - Strutturato",IF(E12<=3.5,"3 - Orbita - Integrato","4 - Gravità - Sistemico / Consistente")))) | G12: =IF(OR(C12="",E12=""),"",E12-C12) | H12: =IF(C12="","",IF(C12>$B$5,"Alta","Bassa")) | I12: =IF(E12="","",IF(E12>$B$5,"Alta","Bassa")) | J12: =IF(AND(H12="Alta",I12="Alta"),"Allineamento virtuoso",IF(AND(H12="Alta",I12="Bassa"),"Potenziale nascosto",IF(AND(H12="Bassa",I12="Alta"),"Sovraesposizione","Area fragile"))) | K12: =IF(J12="Allineamento virtuoso","Area di coerenza: pratiche DEIA mature e disclosure strutturata risultano allineate.",IF(J12="Potenziale nascosto","Area di sottorendicontazione: pratiche più mature della disclosure esterna.",IF(J12="Sovraesposizione","Area di disallineamento comunicativo: la disclosure appare più avanzata della maturità praticata.","Area prioritaria di sviluppo: pratiche e disclosure risultano entrambe deboli."))) | L12: =IF(J12="Area fragile","Alta - rafforzare congiuntamente pratiche e disclosure",IF(J12="Sovraesposizione","Alta - validare evidenze interne e rafforzare pratiche/policy",IF(J12="Potenziale nascosto","Media-Alta - migliorare qualità, granularità e completezza della disclosure","Bassa - consolidare e usare come benchmark interno"))) | M12: =(SUMIF('Mappatura A-B-C'!$I$5:$I$59,$A12,'Mappatura A-B-C'!$T$5:$T$59)+SUMIF('Mappatura A-B-C'!$K$5:$K$59,$A12,'Mappatura A-B-C'!$V$5:$V$59)) | N12: =IF(AND(C12>=1,C12<=4,E12>=1,E12<=4),"OK","ERRORE")
A13: Education & Training | B13: ET | C13: =IFERROR((SUMIF('Mappatura A-B-C'!$I$5:$I$59,$A13,'Mappatura A-B-C'!$S$5:$S$59)+SUMIF('Mappatura A-B-C'!$K$5:$K$59,$A13,'Mappatura A-B-C'!$U$5:$U$59))/(SUMIF('Mappatura A-B-C'!$I$5:$I$59,$A13,'Mappatura A-B-C'!$T$5:$T$59)+SUMIF('Mappatura A-B-C'!$K$5:$K$59,$A13,'Mappatura A-B-C'!$V$5:$V$59)),"") | D13: =IF(C13="","",IF(C13<=1.5,"1 - Deriva - Discontinuo",IF(C13<=2.5,"2 - Rotta - Strutturato",IF(C13<=3.5,"3 - Orbita - Integrato","4 - Gravità - Sistemico / Consistente")))) | E13: =SUMIF('Input reporting B'!$F$9:$F$18,$B$4&"|"&$A13,'Input reporting B'!$D$9:$D$18) | F13: =IF(E13="","",IF(E13<=1.5,"1 - Deriva - Discontinuo",IF(E13<=2.5,"2 - Rotta - Strutturato",IF(E13<=3.5,"3 - Orbita - Integrato","4 - Gravità - Sistemico / Consistente")))) | G13: =IF(OR(C13="",E13=""),"",E13-C13) | H13: =IF(C13="","",IF(C13>$B$5,"Alta","Bassa")) | I13: =IF(E13="","",IF(E13>$B$5,"Alta","Bassa")) | J13: =IF(AND(H13="Alta",I13="Alta"),"Allineamento virtuoso",IF(AND(H13="Alta",I13="Bassa"),"Potenziale nascosto",IF(AND(H13="Bassa",I13="Alta"),"Sovraesposizione","Area fragile"))) | K13: =IF(J13="Allineamento virtuoso","Area di coerenza: pratiche DEIA mature e disclosure strutturata risultano allineate.",IF(J13="Potenziale nascosto","Area di sottorendicontazione: pratiche più mature della disclosure esterna.",IF(J13="Sovraesposizione","Area di disallineamento comunicativo: la disclosure appare più avanzata della maturità praticata.","Area prioritaria di sviluppo: pratiche e disclosure risultano entrambe deboli."))) | L13: =IF(J13="Area fragile","Alta - rafforzare congiuntamente pratiche e disclosure",IF(J13="Sovraesposizione","Alta - validare evidenze interne e rafforzare pratiche/policy",IF(J13="Potenziale nascosto","Media-Alta - migliorare qualità, granularità e completezza della disclosure","Bassa - consolidare e usare come benchmark interno"))) | M13: =(SUMIF('Mappatura A-B-C'!$I$5:$I$59,$A13,'Mappatura A-B-C'!$T$5:$T$59)+SUMIF('Mappatura A-B-C'!$K$5:$K$59,$A13,'Mappatura A-B-C'!$V$5:$V$59)) | N13: =IF(AND(C13>=1,C13<=4,E13>=1,E13<=4),"OK","ERRORE")
A14: Non-discrimination | B14: ND | C14: =IFERROR((SUMIF('Mappatura A-B-C'!$I$5:$I$59,$A14,'Mappatura A-B-C'!$S$5:$S$59)+SUMIF('Mappatura A-B-C'!$K$5:$K$59,$A14,'Mappatura A-B-C'!$U$5:$U$59))/(SUMIF('Mappatura A-B-C'!$I$5:$I$59,$A14,'Mappatura A-B-C'!$T$5:$T$59)+SUMIF('Mappatura A-B-C'!$K$5:$K$59,$A14,'Mappatura A-B-C'!$V$5:$V$59)),"") | D14: =IF(C14="","",IF(C14<=1.5,"1 - Deriva - Discontinuo",IF(C14<=2.5,"2 - Rotta - Strutturato",IF(C14<=3.5,"3 - Orbita - Integrato","4 - Gravità - Sistemico / Consistente")))) | E14: =SUMIF('Input reporting B'!$F$9:$F$18,$B$4&"|"&$A14,'Input reporting B'!$D$9:$D$18) | F14: =IF(E14="","",IF(E14<=1.5,"1 - Deriva - Discontinuo",IF(E14<=2.5,"2 - Rotta - Strutturato",IF(E14<=3.5,"3 - Orbita - Integrato","4 - Gravità - Sistemico / Consistente")))) | G14: =IF(OR(C14="",E14=""),"",E14-C14) | H14: =IF(C14="","",IF(C14>$B$5,"Alta","Bassa")) | I14: =IF(E14="","",IF(E14>$B$5,"Alta","Bassa")) | J14: =IF(AND(H14="Alta",I14="Alta"),"Allineamento virtuoso",IF(AND(H14="Alta",I14="Bassa"),"Potenziale nascosto",IF(AND(H14="Bassa",I14="Alta"),"Sovraesposizione","Area fragile"))) | K14: =IF(J14="Allineamento virtuoso","Area di coerenza: pratiche DEIA mature e disclosure strutturata risultano allineate.",IF(J14="Potenziale nascosto","Area di sottorendicontazione: pratiche più mature della disclosure esterna.",IF(J14="Sovraesposizione","Area di disallineamento comunicativo: la disclosure appare più avanzata della maturità praticata.","Area prioritaria di sviluppo: pratiche e disclosure risultano entrambe deboli."))) | L14: =IF(J14="Area fragile","Alta - rafforzare congiuntamente pratiche e disclosure",IF(J14="Sovraesposizione","Alta - validare evidenze interne e rafforzare pratiche/policy",IF(J14="Potenziale nascosto","Media-Alta - migliorare qualità, granularità e completezza della disclosure","Bassa - consolidare e usare come benchmark interno"))) | M14: =(SUMIF('Mappatura A-B-C'!$I$5:$I$59,$A14,'Mappatura A-B-C'!$T$5:$T$59)+SUMIF('Mappatura A-B-C'!$K$5:$K$59,$A14,'Mappatura A-B-C'!$V$5:$V$59)) | N14: =IF(AND(C14>=1,C14<=4,E14>=1,E14<=4),"OK","ERRORE")
A15: Monitoring | B15: M | C15: =IFERROR((SUMIF('Mappatura A-B-C'!$I$5:$I$59,$A15,'Mappatura A-B-C'!$S$5:$S$59)+SUMIF('Mappatura A-B-C'!$K$5:$K$59,$A15,'Mappatura A-B-C'!$U$5:$U$59))/(SUMIF('Mappatura A-B-C'!$I$5:$I$59,$A15,'Mappatura A-B-C'!$T$5:$T$59)+SUMIF('Mappatura A-B-C'!$K$5:$K$59,$A15,'Mappatura A-B-C'!$V$5:$V$59)),"") | D15: =IF(C15="","",IF(C15<=1.5,"1 - Deriva - Discontinuo",IF(C15<=2.5,"2 - Rotta - Strutturato",IF(C15<=3.5,"3 - Orbita - Integrato","4 - Gravità - Sistemico / Consistente")))) | E15: =SUMIF('Input reporting B'!$F$9:$F$18,$B$4&"|"&$A15,'Input reporting B'!$D$9:$D$18) | F15: =IF(E15="","",IF(E15<=1.5,"1 - Deriva - Discontinuo",IF(E15<=2.5,"2 - Rotta - Strutturato",IF(E15<=3.5,"3 - Orbita - Integrato","4 - Gravità - Sistemico / Consistente")))) | G15: =IF(OR(C15="",E15=""),"",E15-C15) | H15: =IF(C15="","",IF(C15>$B$5,"Alta","Bassa")) | I15: =IF(E15="","",IF(E15>$B$5,"Alta","Bassa")) | J15: =IF(AND(H15="Alta",I15="Alta"),"Allineamento virtuoso",IF(AND(H15="Alta",I15="Bassa"),"Potenziale nascosto",IF(AND(H15="Bassa",I15="Alta"),"Sovraesposizione","Area fragile"))) | K15: =IF(J15="Allineamento virtuoso","Area di coerenza: pratiche DEIA mature e disclosure strutturata risultano allineate.",IF(J15="Potenziale nascosto","Area di sottorendicontazione: pratiche più mature della disclosure esterna.",IF(J15="Sovraesposizione","Area di disallineamento comunicativo: la disclosure appare più avanzata della maturità praticata.","Area prioritaria di sviluppo: pratiche e disclosure risultano entrambe deboli."))) | L15: =IF(J15="Area fragile","Alta - rafforzare congiuntamente pratiche e disclosure",IF(J15="Sovraesposizione","Alta - validare evidenze interne e rafforzare pratiche/policy",IF(J15="Potenziale nascosto","Media-Alta - migliorare qualità, granularità e completezza della disclosure","Bassa - consolidare e usare come benchmark interno"))) | M15: =(SUMIF('Mappatura A-B-C'!$I$5:$I$59,$A15,'Mappatura A-B-C'!$T$5:$T$59)+SUMIF('Mappatura A-B-C'!$K$5:$K$59,$A15,'Mappatura A-B-C'!$V$5:$V$59)) | N15: =IF(AND(C15>=1,C15<=4,E15>=1,E15<=4),"OK","ERRORE")
